Workbook

Sheet Glosario
A1: 1. Gastos directos | B1: Son aquellos que están directamente relacionados con la fabricación del producto o prestación del servicio.
A2: 2. Gastos indirectos | B2: Son aquellos que no están directamente relacionados con la producción, pero son necesarios para el funcionamiento del negocio.
A3: 3. Gastos fijos | B3: Son los gastos que no cambian con el nivel de producción o actividad del negocio. Se mantienen constantes en el corto plazo.
A4: 4. Gastos variables | B4: Son los gastos que fluctúan directamente con el nivel de producción o ventas.
A5: 5. Gastos administrativos | B5: Son los gastos relacionados con la gestión y operación del negocio, que no están vinculados directamente a la producción.
A6: 6. Gastos financieros | B6: Son los costos relacionados con la obtención y uso de recursos financieros.
A7: 7. Gastos de ventas | B7: Son aquellos que se generan al comercializar y distribuir el producto.

Sheet Balances
A1: Balances de requerimientos
C3: Activos que se gestionan en el largo plazo (activos fijos) que reptresentan parte de la inversión que se realiza en un primer momento para poder operar durante un periodo de mediano (5 años) o largo plazo (10 años). | V3: Activos que se gestionan en el corto plazo (activo circulante) que varían en función del volumen de producción y que pueden fluctuar durante periodos cortos de tiempo, por ejemplo en negocios que se caracterizan por ser estacionales)
C5: BALANCE DE MAQUINARIA Y EQUIPO | L5: BALANCE DE OBRA FÍSICA | V5: BALANCE DE PERSONAL | Z5: BALANCE DE INSUMOS
B6: Clasificación | C6: ITEM | D6: Cantidad | E6: Costo unitario | F6: Costo total | G6: Vida útil | H6: Valor de liquidación | I6: Ingreso total | K6: Clasificación | L6: ITEM | M6: Unidad de medida | N6: Cantidad (dimensión) | O6: Costo unitario | P6: Costo total | Q6: Vida útil | R6: Valor residual | S6: Ingreso total | U6: Clasificación | V6: Puesto | W6: Sueldo mensual | Y6: Clasificación | Z6: MATERIAL | AA6: Unidad de medida | AB6: Cantidad | AC6: Costo unitario | AD6: Total
C7: Sierra de mesa o sierra circular industrial | D7: 1 | E7: 30000 | F7: =D7*E7 -> 30000 | G7: 10 | H7: =0.1*E7 -> 3000 | I7: =H7*D7 -> 3000 | L7: Local o bodega | M7: m2 (200) | N7: 1 | O7: 2400000 | P7: =N7*O7 -> 2400000 | Q7: 10 | S7: =R7*N7 -> 0 | V7: Carpintero | W7: 8000 | Z7: Madera | AA7: Metro | AB7: 1 | AC7: 150 | AD7: =AB7*AC7 -> 150
C8: Sierra ingleteadora | D8: 1 | E8: 12000 | F8: =D8*E8 -> 12000 | G8: 10 | H8: =0.1*E8 -> 1200 | I8: =H8*D8 -> 1200 | L8: Baños | M8: m2 (4) | N8: 2 | O8: 45000 | P8: =N8*O8 -> 90000 | Q8: 10 | S8: =R8*N8 -> 0 | V8: Operador de maquinaria | W8: 9000 | Z8: MDF (Fibra densidad media) | AA8: Metro | AB8: 1 | AC8: 400 | AD8: =AB8*AC8 -> 400
C9: Router o fresadora de madera | D9: 1 | E9: 18000 | F9: =D9*E9 -> 18000 | G9: 10 | H9: =0.1*E9 -> 1800 | I9: =H9*D9 -> 1800 | L9: Cocina | M9: m2 (20) | N9: 1 | O9: 80000 | P9: =N9*O9 -> 80000 | Q9: 10 | S9: =R9*N9 -> 0 | V9: Técnico de mantenimiento | W9: 10000 | Z9: Pegamento | AA9: Litro | AB9: 1 | AC9: 140 | AD9: =AB9*AC9 -> 140
C10: Lijadora de banda y disco | D10: 1 | E10: 7000 | F10: =D10*E10 -> 7000 | G10: 10 | H10: =0.1*E10 -> 700 | I10: =H10*D10 -> 700 | L10: Almacén | M10: m2 (100) | N10: 1 | O10: 1200000 | P10: =N10*O10 -> 1200000 | Q10: 10 | S10: =R10*N10 -> 0 | V10: Técnico en acabados | W10: 8400 | Z10: Clavos | AA10: Kg | AB10: 1 | AC10: 90 | AD10: =AB10*AC10 -> 90
C11: Compresor de aire con pistola de clavado | D11: 1 | E11: 8500 | F11: =D11*E11 -> 8500 | G11: 10 | H11: =0.1*E11 -> 850 | I11: =H11*D11 -> 850 | L11: Terreno | M11: m2 (400) | N11: 1 | O11: 2000000 | P11: =N11*O11 -> 2000000 | Q11: 10 | S11: =R11*N11 -> 0 | V11: Inspector de calidad | W11: 8000 | Z11: Grapas | AA11: Kg | AB11: 1 | AC11: 100 | AD11: =AB11*AC11 -> 100
C12: Prensas de ensamblaje | D12: 1 | E12: 6500 | F12: =D12*E12 -> 6500 | G12: 10 | H12: =0.1*E12 -> 650 | I12: =H12*D12 -> 650 | P12: =SUM(P7:P11) -> 5770000 | S12: =SUM(S7:S11) -> 0 | V12: Supervisor de producción | W12: 10000 | Z12: Lija | AA12: Paquete (10) | AB12: 1 | AC12: 200 | AD12: =AB12*AC12 -> 200
C13: Cabina de pintura o barnizado | D13: 1 | E13: 28000 | F13: =D13*E13 -> 28000 | G13: 10 | H13: =0.1*E13 -> 2800 | I13: =H13*D13 -> 2800 | V13: Asistente administrativo | W13: 8500 | Z13: Pintura o barniz | AA13: Litro | AB13: 1 | AC13: 240 | AD13: =AB13*AC13 -> 240
C14: Equipo de pulido y cepillado | D14: 1 | E14: 13500 | F14: =D14*E14 -> 13500 | G14: 10 | H14: =0.1*E14 -> 1350 | I14: =H14*D14 -> 1350 | V14: Encargado de ventas y distribución | W14: 10000 | Z14: Rollo de latex | AA14: Pieza | AB14: 1 | AC14: 80 | AD14: =AB14*AC14 -> 80
C15: Calibrador y escuadras de precisión | D15: 1 | E15: 4500 | F15: =D15*E15 -> 4500 | G15: 10 | H15: =0.1*E15 -> 450 | I15: =H15*D15 -> 450 | V15: Personal de limpieza | W15: 6000 | Z15: Prime o sellador de madera | AA15: Litro | AB15: 1 | AC15: 130 | AD15: =AB15*AC15 -> 130
C16: Mesas de trabajo | D16: 1 | E16: 4800 | F16: =D16*E16 -> 4800 | G16: 10 | H16: =0.1*E16 -> 480 | I16: =H16*D16 -> 480 | V16: Diseñador gráfico | W16: 12000 | Z16: Cartón para embalaje | AA16: Pieza | AB16: 1 | AC16: 12 | AD16: =AB16*AC16 -> 12
C17: Estantes y racks | D17: 1 | E17: 3800 | F17: =D17*E17 -> 3800 | G17: 10 | H17: =0.1*E17 -> 380 | I17: =H17*D17 -> 380 | V17: Administrador | W17: 16000 | Z17: Soporte para colgar marco | AA17: Paquete (100) | AB17: 1 | AC17: 70 | AD17: =AB17*AC17 -> 70
C18: Sistema de aspiración de polvo | D18: 1 | E18: 29000 | F18: =D18*E18 -> 29000 | G18: 10 | H18: =0.1*E18 -> 2900 | I18: =H18*D18 -> 2900 | V18: Contador | W18: 12000 | Z18: Tornillos para soporte | AA18: Caja (100) | AB18: 1 | AC18: 110 | AD18: =AB18*AC18 -> 110
C19: Computadora con software de diseño | D19: 1 | E19: 35000 | F19: =D19*E19 -> 35000 | G19: 5 | H19: =0.1*E19 -> 3500 | I19: =H19*D19 -> 3500 | Z19: Luz (promedio mensual) | AA19: Recibo | AB19: 1 | AC19: 6400 | AD19: =AB19*AC19 -> 6400
C20: Impresora o plotter de gran formato | D20: 1 | E20: 18000 | F20: =D20*E20 -> 18000 | G20: 5 | H20: =0.1*E20 -> 1800 | I20: =H20*D20 -> 1800 | Z20: Combustible | AA20: Litro | AB20: 1 | AC20: 25 | AD20: =AB20*AC20 -> 25
C21: Escritorio | D21: 1 | E21: 3500 | F21: =D21*E21 -> 3500 | G21: 10 | H21: =0.1*E21 -> 350 | I21: =H21*D21 -> 350 | Z21: Internet/telefonía (cuota mensual) | AA21: Recibo | AB21: 1 | AC21: 600 | AD21: =AB21*AC21 -> 600
C22: Silla de oficina | D22: 1 | E22: 2100 | F22: =D22*E22 -> 2100 | G22: 10 | H22: =0.1*E22 -> 210 | I22: =H22*D22 -> 210 | Z22: Papelería (material predeterminado) | AA22: Paquete | AB22: 1 | AC22: 2500 | AD22: =AB22*AC22 -> 2500
C23: Vehículo compacto | D23: 1 | E23: 360000 | F23: =D23*E23 -> 360000 | G23: 10 | H23: =0.1*E23 -> 36000 | I23: =H23*D23 -> 36000 | Z23: Material de limpieza (material predeterminado) | AA23: Paquete | AB23: 1 | AC23: 1200 | AD23: =AB23*AC23 -> 1200
C24: Vehículo de carga | D24: 2 | E24: 450000 | F24: =D24*E24 -> 900000 | G24: 10 | H24: =0.1*E24 -> 45000 | I24: =H24*D24 -> 90000
C25: Pantalla 55 pulgadas | D25: 1 | E25: 12000 | F25: =D25*E25 -> 12000 | G25: 10 | H25: =0.1*E25 -> 1200 | I25: =H25*D25 -> 1200
C26: Soporte para pantalla | D26: 1 | E26: 600 | F26: =D26*E26 -> 600 | G26: 10 | H26: =0.1*E26 -> 60 | I26: =H26*D26 -> 60
F27: =SUM(F7:F26) -> 1496800 | I27: =SUM(I7:I26) -> 149680
A79: Equipo
A104: Esenciales si se usan adhesivos o solventes.
A109: Para fijar decoraciones o etiquetas mediante calor.
A114: Para herramientas neumáticas o equipos automáticos.
A119: Lámparas LED de alta intensidad para las áreas de costura y corte.
A124: Selladoras de plástico.
A125: Máquinas para empaquetado al vacío si es necesario.
A130: Para mover insumos pesados como rollos grandes de tela.
A134: Si deseas optimizar el uso de estos activos, también puedes considerar sistemas de control digital o software de gestión de manufactura (ERP) para coordinar las operaciones del negocio. ¿Te gustaría desarrollar un flujo de trabajo o esquema de procesos con estos activos?
A136: 4o
A138: Dijiste:
A140: dame el precio estimado de cada uno de esos activos en pesos mexicanos
... A341: .

Sheet CT
A1: Capital de trabajo
A3: Tasa de crecimiento anual de producción | P3: 0.03 | AD3: 0.05 | AR3: 0.05 | BF3: 0.05 | BT3: 0.05 | CH3: 0.05 | CV3: 0.05 | DJ3: 0.05 | DX3: 0.05
A4: Tasa de inflación | P4: 0.07 | AD4: 0.06 | AR4: 0.06 | BF4: 0.06 | BT4: 0.06 | CH4: 0.06 | CV4: 0.06 | DJ4: 0.06 | DX4: 0.06
A5: PROGRAMA DE INGRESOS | B5: AÑO 1 | P5: AÑO 2 | AD5: Año 3 | AR5: AÑO 4 | BF5: AÑO 5 | BT5: AÑO 6 | CH5: AÑO 7 | CV5: AÑO 8 | DJ5: AÑO 9 | DX5: AÑO 10
A6: DESCRIPCIÓN | B6: M1 | C6: M2 | D6: M3 | E6: M4 | F6: M5 | G6: M6 | H6: M7 | I6: M8 | J6: M9 | K6: M10 | L6: M11 | M6: M12 | N6: TOTAL | O6: W | P6: M1 | Q6: M2 | R6: M3 | S6: M4 | T6: M5 | U6: M6 | V6: M7 | W6: M8 | X6: M9 | Y6: M10 | Z6: M11 | AA6: M12 | AB6: TOTAL | AC6: W | AD6: M1 | AE6: M2 | AF6: M3 | AG6: M4 | AH6: M5 | AI6: M6 | AJ6: M7 | AK6: M8 | AL6: M9 | AM6: M10 | AN6: M11 | AO6: M12 | AP6: TOTAL | AQ6: W | AR6: M1 | AS6: M2 | AT6: M3 | AU6: M4 | AV6: M5 | AW6: M6 | AX6: M7 | AY6: M8 | AZ6: M9 | BA6: M10 | BB6: M11 | BC6: M12 | BD6: TOTAL | BE6: W | BF6: M1 | BG6: M2 | BH6: M3 | BI6: M4 | BJ6: M5 | BK6: M6 | BL6: M7 | BM6: M8 | BN6: M9 | BO6: M10 | BP6: M11 | BQ6: M12 | BR6: TOTAL | BS6: W | BT6: M1 | BU6: M2 | BV6: M3 | BW6: M4 | BX6: M5 | BY6: M6 | BZ6: M7 | CA6: M8 | CB6: M9 | CC6: M10 | CD6: M11 | CE6: M12 | CF6: TOTAL | CG6: W | CH6: M1 | CI6: M2 | CJ6: M3 | CK6: M4 | CL6: M5 | CM6: M6 | CN6: M7 | CO6: M8 | CP6: M9 | CQ6: M10 | CR6: M11 | CS6: M12 | CT6: TOTAL | CU6: W | CV6: M1 | CW6: M2 | CX6: M3 | CY6: M4 | CZ6: M5 | DA6: M6 | DB6: M7 | DC6: M8 | DD6: M9 | DE6: M10 | DF6: M11 | DG6: M12 | DH6: TOTAL | DI6: W | DJ6: M1 | DK6: M2 | DL6: M3 | DM6: M4 | DN6: M5 | DO6: M6 | DP6: M7 | DQ6: M8 | DR6: M9 | DS6: M10 | DT6: M11 | DU6: M12 | DV6: TOTAL | DW6: W | DX6: M1 | DY6: M2 | DZ6: M3 | EA6: M4 | EB6: M5 | EC6: M6 | ED6: M7 | EE6: M8 | EF6: M9 | EG6: M10 | EH6: M11 | EI6: M12 | EJ6: TOTAL
A7: Unidades de producción (Q) | B7: 1480 | C7: =B7*(1+C3) -> 1480 | D7: =C7*(1+D3) -> 1480 | E7: =D7*(1+E3) -> 1480 | F7: =E7*(1+F3) -> 1480 | G7: =F7*(1+G3) -> 1480 | H7: =G7*(1+H3) -> 1480 | I7: =H7*(1+I3) -> 1480 | J7: =I7*(1+J3) -> 1480 | ... M7: =L7*(1+M3) -> 1480 | N7: =SUM(B7:M7) -> 17760 | O7: 1 | P7: =$O$7*B7*(1+$P$3) -> 1524.4 | Q7: =$O$7*C7*(1+$P$3) -> 1524.4 | R7: =$O$7*D7*(1+$P$3) -> 1524.4 | S7: =$O$7*E7*(1+$P$3) -> 1524.4 | T7: =$O$7*F7*(1+$P$3) -> 1524.4 | U7: =$O$7*G7*(1+$P$3) -> 1524.4 | V7: =$O$7*H7*(1+$P$3) -> 1524.4 | W7: =$O$7*I7*(1+$P$3) -> 1524.4 | ... AA7: =$O$7*M7*(1+$P$3) -> 1524.4 | AB7: =SUM(P7:AA7) -> 18292.8 | AC7: 1 | AD7: =$AC7*P7*(1+$AD$3) -> 1600.62 | AE7: =$AC7*Q7*(1+$AD$3) -> 1600.62 | AF7: =$AC7*R7*(1+$AD$3) -> 1600.62 | AG7: =$AC7*S7*(1+$AD$3) -> 1600.62 | AH7: =$AC7*T7*(1+$AD$3) -> 1600.62 | AI7: =$AC7*U7*(1+$AD$3) -> 1600.62 | AJ7: =$AC7*V7*(1+$AD$3) -> 1600.62 | AK7: =$AC7*W7*(1+$AD$3) -> 1600.62 | ... AO7: =$AC7*AA7*(1+$AD$3) -> 1600.62 | AP7: =SUM(AD7:AO7) -> 19207.44 | AQ7: 1 | AR7: =$AQ7*AD7*(1+$AR$3) -> 1680.651 | AS7: =$AQ7*AE7*(1+$AR$3) -> 1680.651 | AT7: =$AQ7*AF7*(1+$AR$3) -> 1680.651 | AU7: =$AQ7*AG7*(1+$AR$3) -> 1680.651 | AV7: =$AQ7*AH7*(1+$AR$3) -> 1680.651 | AW7: =$AQ7*AI7*(1+$AR$3) -> 1680.651 | AX7: =$AQ7*AJ7*(1+$AR$3) -> 1680.651 | AY7: =$AQ7*AK7*(1+$AR$3) -> 1680.651 | ... BC7: =$AQ7*AO7*(1+$AR$3) -> 1680.651 | BD7: =SUM(AR7:BC7) -> 20167.812 | BE7: 1 | BF7: =$BE7*AR7*(1+$BF$3) -> 1764.6836 | BG7: =$BE7*AS7*(1+$BF$3) -> 1764.6836 | BH7: =$BE7*AT7*(1+$BF$3) -> 1764.6836 | BI7: =$BE7*AU7*(1+$BF$3) -> 1764.6836 | BJ7: =$BE7*AV7*(1+$BF$3) -> 1764.6836 | BK7: =$BE7*AW7*(1+$BF$3) -> 1764.6836 | BL7: =$BE7*AX7*(1+$BF$3) -> 1764.6836 | BM7: =$BE7*AY7*(1+$BF$3) -> 1764.6836 | ... BQ7: =$BE7*BC7*(1+$BF$3) -> 1764.6836 | BR7: =SUM(BF7:BQ7) -> 21176.203 | BS7: 1 | BT7: =$BS7*BF7*(1+$BT$3) -> 1852.9177 | BU7: =$BS7*BG7*(1+$BT$3) -> 1852.9177 | BV7: =$BS7*BH7*(1+$BT$3) -> 1852.9177 | BW7: =$BS7*BI7*(1+$BT$3) -> 1852.9177 | BX7: =$BS7*BJ7*(1+$BT$3) -> 1852.9177 | BY7: =$BS7*BK7*(1+$BT$3) -> 1852.9177 | BZ7: =$BS7*BL7*(1+$BT$3) -> 1852.9177 | CA7: =$BS7*BM7*(1+$BT$3) -> 1852.9177 | ... CE7: =$BS7*BQ7*(1+$BT$3) -> 1852.9177 | CF7: =SUM(BT7:CE7) -> 22235.013 | CG7: 1 | CH7: =$CG7*BT7*(1+$CH$3) -> 1945.5636 | CI7: =$CG7*BU7*(1+$CH$3) -> 1945.5636 | CJ7: =$CG7*BV7*(1+$CH$3) -> 1945.5636 | CK7: =$CG7*BW7*(1+$CH$3) -> 1945.5636 | CL7: =$CG7*BX7*(1+$CH$3) -> 1945.5636 | CM7: =$CG7*BY7*(1+$CH$3) -> 1945.5636 | CN7: =$CG7*BZ7*(1+$CH$3) -> 1945.5636 | CO7: =$CG7*CA7*(1+$CH$3) -> 1945.5636 | ... CS7: =$CG7*CE7*(1+$CH$3) -> 1945.5636 | CT7: =SUM(CH7:CS7) -> 23346.763 | CU7: 1 | CV7: =$CU7*CH7*(1+$CV$3) -> 2042.8418 | CW7: =$CU7*CI7*(1+$CV$3) -> 2042.8418 | CX7: =$CU7*CJ7*(1+$CV$3) -> 2042.8418 | CY7: =$CU7*CK7*(1+$CV$3) -> 2042.8418 | CZ7: =$CU7*CL7*(1+$CV$3) -> 2042.8418 | DA7: =$CU7*CM7*(1+$CV$3) -> 2042.8418 | DB7: =$CU7*CN7*(1+$CV$3) -> 2042.8418 | DC7: =$CU7*CO7*(1+$CV$3) -> 2042.8418 | ... DG7: =$CU7*CS7*(1+$CV$3) -> 2042.8418 | DH7: =SUM(CV7:DG7) -> 24514.102 | DI7: 1 | DJ7: =$DI7*CV7*(1+$DJ$3) -> 2144.9839 | DK7: =$DI7*CW7*(1+$DJ$3) -> 2144.9839 | DL7: =$DI7*CX7*(1+$DJ$3) -> 2144.9839 | DM7: =$DI7*CY7*(1+$DJ$3) -> 2144.9839 | DN7: =$DI7*CZ7*(1+$DJ$3) -> 2144.9839 | DO7: =$DI7*DA7*(1+$DJ$3) -> 2144.9839 | DP7: =$DI7*DB7*(1+$DJ$3) -> 2144.9839 | DQ7: =$DI7*DC7*(1+$DJ$3) -> 2144.9839 | ... DU7: =$DI7*DG7*(1+$DJ$3) -> 2144.9839 | DV7: =SUM(DJ7:DU7) -> 25739.807 | DW7: 1 | DX7: =$DW7*DJ7*(1+$DX$3) -> 2252.2331 | DY7: =$DW7*DK7*(1+$DX$3) -> 2252.2331 | DZ7: =$DW7*DL7*(1+$DX$3) -> 2252.2331 | EA7: =$DW7*DM7*(1+$DX$3) -> 2252.2331 | EB7: =$DW7*DN7*(1+$DX$3) -> 2252.2331 | EC7: =$DW7*DO7*(1+$DX$3) -> 2252.2331 | ED7: =$DW7*DP7*(1+$DX$3) -> 2252.2331 | EE7: =$DW7*DQ7*(1+$DX$3) -> 2252.2331 | ... EI7: =$DW7*DU7*(1+$DX$3) -> 2252.2331 | EJ7: =SUM(DX7:EI7) -> 27026.797
A8: Precio de venta (P) | B8: =400 -> 400 | C8: =B8 -> 400 | D8: =C8 -> 400 | E8: =D8 -> 400 | F8: =E8 -> 400 | G8: =F8 -> 400 | H8: =G8 -> 400 | I8: =H8 -> 400 | J8: =I8 -> 400 | ... M8: =L8 -> 400 | N8: =IF(N7>0,(SUMPRODUCT(B7:M7,B8:M8)/N7),0) -> 400 | O8: 1 | P8: =$O$8*B8*(1+$P$4) -> 428 | Q8: =$O$8*C8*(1+$P$4) -> 428 | R8: =$O$8*D8*(1+$P$4) -> 428 | S8: =$O$8*E8*(1+$P$4) -> 428 | T8: =$O$8*F8*(1+$P$4) -> 428 | U8: =$O$8*G8*(1+$P$4) -> 428 | V8: =$O$8*H8*(1+$P$4) -> 428 | W8: =$O$8*I8*(1+$P$4) -> 428 | ... AA8: =$O$8*M8*(1+$P$4) -> 428 | AB8: =IF(AB7>0,(SUMPRODUCT(P7:AA7,P8:AA8)/AB7),0) -> 428 | AC8: 1 | AD8: =$AC8*P8*(1+$AD$4) -> 453.68 | AE8: =$AC8*Q8*(1+$AD$4) -> 453.68 | AF8: =$AC8*R8*(1+$AD$4) -> 453.68 | AG8: =$AC8*S8*(1+$AD$4) -> 453.68 | AH8: =$AC8*T8*(1+$AD$4) -> 453.68 | AI8: =$AC8*U8*(1+$AD$4) -> 453.68 | AJ8: =$AC8*V8*(1+$AD$4) -> 453.68 | AK8: =$AC8*W8*(1+$AD$4) -> 453.68 | ... AO8: =$AC8*AA8*(1+$AD$4) -> 453.68 | AP8: =IF(AP7>0,(SUMPRODUCT(AD7:AO7,AD8:AO8)/AP7),0) -> 453.68 | AQ8: 1 | AR8: =$AQ8*AD8*(1+$AR$4) -> 480.9008 | AS8: =$AQ8*AE8*(1+$AR$4) -> 480.9008 | AT8: =$AQ8*AF8*(1+$AR$4) -> 480.9008 | AU8: =$AQ8*AG8*(1+$AR$4) -> 480.9008 | AV8: =$AQ8*AH8*(1+$AR$4) -> 480.9008 | AW8: =$AQ8*AI8*(1+$AR$4) -> 480.9008 | AX8: =$AQ8*AJ8*(1+$AR$4) -> 480.9008 | AY8: =$AQ8*AK8*(1+$AR$4) -> 480.9008 | ... BC8: =$AQ8*AO8*(1+$AR$4) -> 480.9008 | BD8: =IF(BD7>0,(SUMPRODUCT(AR7:BC7,AR8:BC8)/BD7),0) -> 480.9008 | BE8: 1 | BF8: =$BE8*AR8*(1+$BF$4) -> 509.75485 | BG8: =$BE8*AS8*(1+$BF$4) -> 509.75485 | BH8: =$BE8*AT8*(1+$BF$4) -> 509.75485 | BI8: =$BE8*AU8*(1+$BF$4) -> 509.75485 | BJ8: =$BE8*AV8*(1+$BF$4) -> 509.75485 | BK8: =$BE8*AW8*(1+$BF$4) -> 509.75485 | BL8: =$BE8*AX8*(1+$BF$4) -> 509.75485 | BM8: =$BE8*AY8*(1+$BF$4) -> 509.75485 | ... BQ8: =$BE8*BC8*(1+$BF$4) -> 509.75485 | BR8: =IF(BR7>0,(SUMPRODUCT(BF7:BQ7,BF8:BQ8)/BR7),0) -> 509.75485 | BS8: 1 | BT8: =$BS8*BF8*(1+$BT$4) -> 540.34014 | BU8: =$BS8*BG8*(1+$BT$4) -> 540.34014 | BV8: =$BS8*BH8*(1+$BT$4) -> 540.34014 | BW8: =$BS8*BI8*(1+$BT$4) -> 540.34014 | BX8: =$BS8*BJ8*(1+$BT$4) -> 540.34014 | BY8: =$BS8*BK8*(1+$BT$4) -> 540.34014 | BZ8: =$BS8*BL8*(1+$BT$4) -> 540.34014 | CA8: =$BS8*BM8*(1+$BT$4) -> 540.34014 | ... CE8: =$BS8*BQ8*(1+$BT$4) -> 540.34014 | CF8: =IF(CF7>0,(SUMPRODUCT(BT7:CE7,BT8:CE8)/CF7),0) -> 540.34014 | CG8: 1 | CH8: =$CG8*BT8*(1+$CH$4) -> 572.76055 | CI8: =$CG8*BU8*(1+$CH$4) -> 572.76055 | CJ8: =$CG8*BV8*(1+$CH$4) -> 572.76055 | CK8: =$CG8*BW8*(1+$CH$4) -> 572.76055 | CL8: =$CG8*BX8*(1+$CH$4) -> 572.76055 | CM8: =$CG8*BY8*(1+$CH$4) -> 572.76055 | CN8: =$CG8*BZ8*(1+$CH$4) -> 572.76055 | CO8: =$CG8*CA8*(1+$CH$4) -> 572.76055 | ... CS8: =$CG8*CE8*(1+$CH$4) -> 572.76055 | CT8: =IF(CT7>0,(SUMPRODUCT(CH7:CS7,CH8:CS8)/CT7),0) -> 572.76055 | CU8: 1 | CV8: =$CU8*CH8*(1+$CV$4) -> 607.12618 | CW8: =$CU8*CI8*(1+$CV$4) -> 607.12618 | CX8: =$CU8*CJ8*(1+$CV$4) -> 607.12618 | CY8: =$CU8*CK8*(1+$CV$4) -> 607.12618 | CZ8: =$CU8*CL8*(1+$CV$4) -> 607.12618 | DA8: =$CU8*CM8*(1+$CV$4) -> 607.12618 | DB8: =$CU8*CN8*(1+$CV$4) -> 607.12618 | DC8: =$CU8*CO8*(1+$CV$4) -> 607.12618 | ... DG8: =$CU8*CS8*(1+$CV$4) -> 607.12618 | DH8: =IF(DH7>0,(SUMPRODUCT(CV7:DG7,CV8:DG8)/DH7),0) -> 607.12618 | DI8: 1 | DJ8: =$DI8*CV8*(1+$DJ$4) -> 643.55375 | DK8: =$DI8*CW8*(1+$DJ$4) -> 643.55375 | DL8: =$DI8*CX8*(1+$DJ$4) -> 643.55375 | DM8: =$DI8*CY8*(1+$DJ$4) -> 643.55375 | DN8: =$DI8*CZ8*(1+$DJ$4) -> 643.55375 | DO8: =$DI8*DA8*(1+$DJ$4) -> 643.55375 | DP8: =$DI8*DB8*(1+$DJ$4) -> 643.55375 | DQ8: =$DI8*DC8*(1+$DJ$4) -> 643.55375 | ... DU8: =$DI8*DG8*(1+$DJ$4) -> 643.55375 | DV8: =IF(DV7>0,(SUMPRODUCT(DJ7:DU7,DJ8:DU8)/DV7),0) -> 643.55375 | DW8: 1 | DX8: =$DW8*DJ8*(1+$DX$4) -> 682.16698 | DY8: =$DW8*DK8*(1+$DX$4) -> 682.16698 | DZ8: =$DW8*DL8*(1+$DX$4) -> 682.16698 | EA8: =$DW8*DM8*(1+$DX$4) -> 682.16698 | EB8: =$DW8*DN8*(1+$DX$4) -> 682.16698 | EC8: =$DW8*DO8*(1+$DX$4) -> 682.16698 | ED8: =$DW8*DP8*(1+$DX$4) -> 682.16698 | EE8: =$DW8*DQ8*(1+$DX$4) -> 682.16698 | ... EI8: =$DW8*DU8*(1+$DX$4) -> 682.16698 | EJ8: =IF(EJ7>0,(SUMPRODUCT(DX7:EI7,DX8:EI8)/EJ7),0) -> 682.16698
A9: Ventas totales (VT) | B9: =B7*B8 -> 592000 | C9: =C7*C8 -> 592000 | D9: =D7*D8 -> 592000 | E9: =E7*E8 -> 592000 | F9: =F7*F8 -> 592000 | G9: =G7*G8 -> 592000 | H9: =H7*H8 -> 592000 | I9: =I7*I8 -> 592000 | ... N9: =N7*N8 -> 7104000 | P9: =P7*P8 -> 652443.2 | Q9: =Q7*Q8 -> 652443.2 | R9: =R7*R8 -> 652443.2 | S9: =S7*S8 -> 652443.2 | T9: =T7*T8 -> 652443.2 | U9: =U7*U8 -> 652443.2 | V9: =V7*V8 -> 652443.2 | W9: =W7*W8 -> 652443.2 | ... AB9: =AB7*AB8 -> 7829318.4 | AD9: =AD7*AD8 -> 726169.28 | AE9: =AE7*AE8 -> 726169.28 | AF9: =AF7*AF8 -> 726169.28 | AG9: =AG7*AG8 -> 726169.28 | AH9: =AH7*AH8 -> 726169.28 | AI9: =AI7*AI8 -> 726169.28 | AJ9: =AJ7*AJ8 -> 726169.28 | AK9: =AK7*AK8 -> 726169.28 | ... AP9: =AP7*AP8 -> 8714031.4 | AR9: =AR7*AR8 -> 808226.41 | AS9: =AS7*AS8 -> 808226.41 | AT9: =AT7*AT8 -> 808226.41 | AU9: =AU7*AU8 -> 808226.41 | AV9: =AV7*AV8 -> 808226.41 | AW9: =AW7*AW8 -> 808226.41 | AX9: =AX7*AX8 -> 808226.41 | AY9: =AY7*AY8 -> 808226.41 | ... BD9: =BD7*BD8 -> 9698716.9 | BF9: =BF7*BF8 -> 899555.99 | BG9: =BG7*BG8 -> 899555.99 | BH9: =BH7*BH8 -> 899555.99 | BI9: =BI7*BI8 -> 899555.99 | BJ9: =BJ7*BJ8 -> 899555.99 | BK9: =BK7*BK8 -> 899555.99 | BL9: =BL7*BL8 -> 899555.99 | BM9: =BM7*BM8 -> 899555.99 | ... BR9: =BR7*BR8 -> 10794672 | BT9: =BT7*BT8 -> 1001205.8 | BU9: =BU7*BU8 -> 1001205.8 | BV9: =BV7*BV8 -> 1001205.8 | BW9: =BW7*BW8 -> 1001205.8 | BX9: =BX7*BX8 -> 1001205.8 | BY9: =BY7*BY8 -> 1001205.8 | BZ9: =BZ7*BZ8 -> 1001205.8 | CA9: =CA7*CA8 -> 1001205.8 | ... CF9: =CF7*CF8 -> 12014470 | CH9: =CH7*CH8 -> 1114342.1 | CI9: =CI7*CI8 -> 1114342.1 | CJ9: =CJ7*CJ8 -> 1114342.1 | CK9: =CK7*CK8 -> 1114342.1 | CL9: =CL7*CL8 -> 1114342.1 | CM9: =CM7*CM8 -> 1114342.1 | CN9: =CN7*CN8 -> 1114342.1 | CO9: =CO7*CO8 -> 1114342.1 | ... CT9: =CT7*CT8 -> 13372105 | CV9: =CV7*CV8 -> 1240262.7 | CW9: =CW7*CW8 -> 1240262.7 | CX9: =CX7*CX8 -> 1240262.7 | CY9: =CY7*CY8 -> 1240262.7 | CZ9: =CZ7*CZ8 -> 1240262.7 | DA9: =DA7*DA8 -> 1240262.7 | DB9: =DB7*DB8 -> 1240262.7 | DC9: =DC7*DC8 -> 1240262.7 | ... DH9: =DH7*DH8 -> 14883153 | DJ9: =DJ7*DJ8 -> 1380412.4 | DK9: =DK7*DK8 -> 1380412.4 | DL9: =DL7*DL8 -> 1380412.4 | DM9: =DM7*DM8 -> 1380412.4 | DN9: =DN7*DN8 -> 1380412.4 | DO9: =DO7*DO8 -> 1380412.4 | DP9: =DP7*DP8 -> 1380412.4 | DQ9: =DQ7*DQ8 -> 1380412.4 | ... DV9: =DV7*DV8 -> 16564949 | DX9: =DX7*DX8 -> 1536399 | DY9: =DY7*DY8 -> 1536399 | DZ9: =DZ7*DZ8 -> 1536399 | EA9: =EA7*EA8 -> 1536399 | EB9: =EB7*EB8 -> 1536399 | EC9: =EC7*EC8 -> 1536399 | ED9: =ED7*ED8 -> 1536399 | EE9: =EE7*EE8 -> 1536399 | ... EJ9: =EJ7*EJ8 -> 18436788
A10: Otros ingresos (OI) | N10: =SUM(B10:M10) -> 0 | AB10: =SUM(P10:AA10) -> 0 | AP10: =SUM(AD10:AO10) -> 0 | BD10: =SUM(AR10:BC10) -> 0 | BR10: =SUM(BF10:BQ10) -> 0 | CF10: =SUM(BT10:CE10) -> 0 | CT10: =SUM(CH10:CS10) -> 0 | DH10: =SUM(CV10:DG10) -> 0 | DV10: =SUM(DJ10:DU10) -> 0 | EJ10: =SUM(DX10:EI10) -> 0
A11: Ingresos totales (IT) | B11: =B9+B10 -> 592000 | C11: =C9+C10 -> 592000 | D11: =D9+D10 -> 592000 | E11: =E9+E10 -> 592000 | F11: =F9+F10 -> 592000 | G11: =G9+G10 -> 592000 | H11: =H9+H10 -> 592000 | I11: =I9+I10 -> 592000 | ... N11: =N9+N10 -> 7104000 | P11: =P9+P10 -> 652443.2 | Q11: =Q9+Q10 -> 652443.2 | R11: =R9+R10 -> 652443.2 | S11: =S9+S10 -> 652443.2 | T11: =T9+T10 -> 652443.2 | U11: =U9+U10 -> 652443.2 | V11: =V9+V10 -> 652443.2 | W11: =W9+W10 -> 652443.2 | ... AB11: =AB9+AB10 -> 7829318.4 | AD11: =AD9+AD10 -> 726169.28 | AE11: =AE9+AE10 -> 726169.28 | AF11: =AF9+AF10 -> 726169.28 | AG11: =AG9+AG10 -> 726169.28 | AH11: =AH9+AH10 -> 726169.28 | AI11: =AI9+AI10 -> 726169.28 | AJ11: =AJ9+AJ10 -> 726169.28 | AK11: =AK9+AK10 -> 726169.28 | ... AP11: =AP9+AP10 -> 8714031.4 | AR11: =AR9+AR10 -> 808226.41 | AS11: =AS9+AS10 -> 808226.41 | AT11: =AT9+AT10 -> 808226.41 | AU11: =AU9+AU10 -> 808226.41 | AV11: =AV9+AV10 -> 808226.41 | AW11: =AW9+AW10 -> 808226.41 | AX11: =AX9+AX10 -> 808226.41 | AY11: =AY9+AY10 -> 808226.41 | ... BD11: =BD9+BD10 -> 9698716.9 | BF11: =BF9+BF10 -> 899555.99 | BG11: =BG9+BG10 -> 899555.99 | BH11: =BH9+BH10 -> 899555.99 | BI11: =BI9+BI10 -> 899555.99 | BJ11: =BJ9+BJ10 -> 899555.99 | BK11: =BK9+BK10 -> 899555.99 | BL11: =BL9+BL10 -> 899555.99 | BM11: =BM9+BM10 -> 899555.99 | ... BR11: =BR9+BR10 -> 10794672 | BT11: =BT9+BT10 -> 1001205.8 | BU11: =BU9+BU10 -> 1001205.8 | BV11: =BV9+BV10 -> 1001205.8 | BW11: =BW9+BW10 -> 1001205.8 | BX11: =BX9+BX10 -> 1001205.8 | BY11: =BY9+BY10 -> 1001205.8 | BZ11: =BZ9+BZ10 -> 1001205.8 | CA11: =CA9+CA10 -> 1001205.8 | ... CF11: =CF9+CF10 -> 12014470 | CH11: =CH9+CH10 -> 1114342.1 | CI11: =CI9+CI10 -> 1114342.1 | CJ11: =CJ9+CJ10 -> 1114342.1 | CK11: =CK9+CK10 -> 1114342.1 | CL11: =CL9+CL10 -> 1114342.1 | CM11: =CM9+CM10 -> 1114342.1 | CN11: =CN9+CN10 -> 1114342.1 | CO11: =CO9+CO10 -> 1114342.1 | ... CT11: =CT9+CT10 -> 13372105 | CV11: =CV9+CV10 -> 1240262.7 | CW11: =CW9+CW10 -> 1240262.7 | CX11: =CX9+CX10 -> 1240262.7 | CY11: =CY9+CY10 -> 1240262.7 | CZ11: =CZ9+CZ10 -> 1240262.7 | DA11: =DA9+DA10 -> 1240262.7 | DB11: =DB9+DB10 -> 1240262.7 | DC11: =DC9+DC10 -> 1240262.7 | ... DH11: =DH9+DH10 -> 14883153 | DJ11: =DJ9+DJ10 -> 1380412.4 | DK11: =DK9+DK10 -> 1380412.4 | DL11: =DL9+DL10 -> 1380412.4 | DM11: =DM9+DM10 -> 1380412.4 | DN11: =DN9+DN10 -> 1380412.4 | DO11: =DO9+DO10 -> 1380412.4 | DP11: =DP9+DP10 -> 1380412.4 | DQ11: =DQ9+DQ10 -> 1380412.4 | ... DV11: =DV9+DV10 -> 16564949 | DX11: =DX9+DX10 -> 1536399 | DY11: =DY9+DY10 -> 1536399 | DZ11: =DZ9+DZ10 -> 1536399 | EA11: =EA9+EA10 -> 1536399 | EB11: =EB9+EB10 -> 1536399 | EC11: =EC9+EC10 -> 1536399 | ED11: =ED9+ED10 -> 1536399 | EE11: =EE9+EE10 -> 1536399 | ... EJ11: =EJ9+EJ10 -> 18436788
A12: PROGRAMA DE EGRESOS | B12: AÑO 1 | P12: AÑO 2 | AD12: Año 3 | AR12: AÑO 4 | BF12: AÑO 5 | BT12: AÑO 6 | CH12: AÑO 7 | CV12: AÑO 8 | DJ12: AÑO 9 | DX12: AÑO 10
A13: DESCRIPCIÓN | B13: M1 | C13: M2 | D13: M3 | E13: M4 | F13: M5 | G13: M6 | H13: M7 | I13: M8 | J13: M9 | K13: M10 | L13: M11 | M13: M12 | N13: TOTAL | P13: M1 | Q13: M2 | R13: M3 | S13: M4 | T13: M5 | U13: M6 | V13: M7 | W13: M8 | X13: M9 | Y13: M10 | Z13: M11 | AA13: M12 | AB13: TOTAL | AD13: M1 | AE13: M2 | AF13: M3 | AG13: M4 | AH13: M5 | AI13: M6 | AJ13: M7 | AK13: M8 | AL13: M9 | AM13: M10 | AN13: M11 | AO13: M12 | AP13: TOTAL | AR13: M1 | AS13: M2 | AT13: M3 | AU13: M4 | AV13: M5 | AW13: M6 | AX13: M7 | AY13: M8 | AZ13: M9 | BA13: M10 | BB13: M11 | BC13: M12 | BD13: TOTAL | BF13: M1 | BG13: M2 | BH13: M3 | BI13: M4 | BJ13: M5 | BK13: M6 | BL13: M7 | BM13: M8 | BN13: M9 | BO13: M10 | BP13: M11 | BQ13: M12 | BR13: TOTAL | BT13: M1 | BU13: M2 | BV13: M3 | BW13: M4 | BX13: M5 | BY13: M6 | BZ13: M7 | CA13: M8 | CB13: M9 | CC13: M10 | CD13: M11 | CE13: M12 | CF13: TOTAL | CH13: M1 | CI13: M2 | CJ13: M3 | CK13: M4 | CL13: M5 | CM13: M6 | CN13: M7 | CO13: M8 | CP13: M9 | CQ13: M10 | CR13: M11 | CS13: M12 | CT13: TOTAL | CV13: M1 | CW13: M2 | CX13: M3 | CY13: M4 | CZ13: M5 | DA13: M6 | DB13: M7 | DC13: M8 | DD13: M9 | DE13: M10 | DF13: M11 | DG13: M12 | DH13: TOTAL | DJ13: M1 | DK13: M2 | DL13: M3 | DM13: M4 | DN13: M5 | DO13: M6 | DP13: M7 | DQ13: M8 | DR13: M9 | DS13: M10 | DT13: M11 | DU13: M12 | DV13: TOTAL | DX13: M1 | DY13: M2 | DZ13: M3 | EA13: M4 | EB13: M5 | EC13: M6 | ED13: M7 | EE13: M8 | EF13: M9 | EG13: M10 | EH13: M11 | EI13: M12 | EJ13: TOTAL
A14: 1. Costo de ventas | B14: =B15+B26+B30+B35 -> 362590 | C14: =C15+C26+C30+C35 -> 362590 | D14: =D15+D26+D30+D35 -> 362590 | E14: =E15+E26+E30+E35 -> 362590 | F14: =F15+F26+F30+F35 -> 362590 | G14: =G15+G26+G30+G35 -> 362590 | H14: =H15+H26+H30+H35 -> 362590 | I14: =I15+I26+I30+I35 -> 362590 | ... M14: =M15+M26+M30+M35 -> 362590 | N14: =SUM(B14:M14) -> 4351080 | P14: =P15+P26+P30+P35 -> 397029.6 | Q14: =Q15+Q26+Q30+Q35 -> 397029.6 | R14: =R15+R26+R30+R35 -> 397029.6 | S14: =S15+S26+S30+S35 -> 397029.6 | T14: =T15+T26+T30+T35 -> 397029.6 | U14: =U15+U26+U30+U35 -> 397029.6 | V14: =V15+V26+V30+V35 -> 397029.6 | W14: =W15+W26+W30+W35 -> 397029.6 | ... AA14: =AA15+AA26+AA30+AA35 -> 397029.6 | AB14: =SUM(P14:AA14) -> 4764355.2 | AD14: =AD15+AD26+AD30+AD35 -> 437334.46 | AE14: =AE15+AE26+AE30+AE35 -> 437334.46 | AF14: =AF15+AF26+AF30+AF35 -> 437334.46 | AG14: =AG15+AG26+AG30+AG35 -> 437334.46 | AH14: =AH15+AH26+AH30+AH35 -> 437334.46 | AI14: =AI15+AI26+AI30+AI35 -> 437334.46 | AJ14: =AJ15+AJ26+AJ30+AJ35 -> 437334.46 | AK14: =AK15+AK26+AK30+AK35 -> 437334.46 | ... AO14: =AO15+AO26+AO30+AO35 -> 437334.46 | AP14: =SUM(AD14:AO14) -> 5248013.5 | AR14: =AR15+AR26+AR30+AR35 -> 481920.2 | AS14: =AS15+AS26+AS30+AS35 -> 481920.2 | AT14: =AT15+AT26+AT30+AT35 -> 481920.2 | AU14: =AU15+AU26+AU30+AU35 -> 481920.2 | AV14: =AV15+AV26+AV30+AV35 -> 481920.2 | AW14: =AW15+AW26+AW30+AW35 -> 481920.2 | AX14: =AX15+AX26+AX30+AX35 -> 481920.2 | AY14: =AY15+AY26+AY30+AY35 -> 481920.2 | ... BC14: =BC15+BC26+BC30+BC35 -> 481920.2 | BD14: =SUM(AR14:BC14) -> 5783042.4 | BF14: =BF15+BF26+BF30+BF35 -> 531254.15 | BG14: =BG15+BG26+BG30+BG35 -> 531254.15 | BH14: =BH15+BH26+BH30+BH35 -> 531254.15 | BI14: =BI15+BI26+BI30+BI35 -> 531254.15 | BJ14: =BJ15+BJ26+BJ30+BJ35 -> 531254.15 | BK14: =BK15+BK26+BK30+BK35 -> 531254.15 | BL14: =BL15+BL26+BL30+BL35 -> 531254.15 | BM14: =BM15+BM26+BM30+BM35 -> 531254.15 | ... BQ14: =BQ15+BQ26+BQ30+BQ35 -> 531254.15 | BR14: =SUM(BF14:BQ14) -> 6375049.8 | BT14: =BT15+BT26+BT30+BT35 -> 585855.45 | BU14: =BU15+BU26+BU30+BU35 -> 585855.45 | BV14: =BV15+BV26+BV30+BV35 -> 585855.45 | BW14: =BW15+BW26+BW30+BW35 -> 585855.45 | BX14: =BX15+BX26+BX30+BX35 -> 585855.45 | BY14: =BY15+BY26+BY30+BY35 -> 585855.45 | BZ14: =BZ15+BZ26+BZ30+BZ35 -> 585855.45 | CA14: =CA15+CA26+CA30+CA35 -> 585855.45 | ... CE14: =CE15+CE26+CE30+CE35 -> 585855.45 | CF14: =SUM(BT14:CE14) -> 7030265.4 | CH14: =CH15+CH26+CH30+CH35 -> 646300.87 | CI14: =CI15+CI26+CI30+CI35 -> 646300.87 | CJ14: =CJ15+CJ26+CJ30+CJ35 -> 646300.87 | CK14: =CK15+CK26+CK30+CK35 -> 646300.87 | CL14: =CL15+CL26+CL30+CL35 -> 646300.87 | CM14: =CM15+CM26+CM30+CM35 -> 646300.87 | CN14: =CN15+CN26+CN30+CN35 -> 646300.87 | CO14: =CO15+CO26+CO30+CO35 -> 646300.87 | ... CS14: =CS15+CS26+CS30+CS35 -> 646300.87 | CT14: =SUM(CH14:CS14) -> 7755610.4 | CV14: =CV15+CV26+CV30+CV35 -> 713231.25 | CW14: =CW15+CW26+CW30+CW35 -> 713231.25 | CX14: =CX15+CX26+CX30+CX35 -> 713231.25 | CY14: =CY15+CY26+CY30+CY35 -> 713231.25 | CZ14: =CZ15+CZ26+CZ30+CZ35 -> 713231.25 | DA14: =DA15+DA26+DA30+DA35 -> 713231.25 | DB14: =DB15+DB26+DB30+DB35 -> 713231.25 | DC14: =DC15+DC26+DC30+DC35 -> 713231.25 | ... DG14: =DG15+DG26+DG30+DG35 -> 713231.25 | DH14: =SUM(CV14:DG14) -> 8558775 | DJ14: =DJ15+DJ26+DJ30+DJ35 -> 787358.67 | DK14: =DK15+DK26+DK30+DK35 -> 787358.67 | DL14: =DL15+DL26+DL30+DL35 -> 787358.67 | DM14: =DM15+DM26+DM30+DM35 -> 787358.67 | DN14: =DN15+DN26+DN30+DN35 -> 787358.67 | DO14: =DO15+DO26+DO30+DO35 -> 787358.67 | DP14: =DP15+DP26+DP30+DP35 -> 787358.67 | DQ14: =DQ15+DQ26+DQ30+DQ35 -> 787358.67 | ... DU14: =DU15+DU26+DU30+DU35 -> 787358.67 | DV14: =SUM(DJ14:DU14) -> 9448304 | DX14: =DX15+DX26+DX30+DX35 -> 869474.42 | DY14: =DY15+DY26+DY30+DY35 -> 869474.42 | DZ14: =DZ15+DZ26+DZ30+DZ35 -> 869474.42 | EA14: =EA15+EA26+EA30+EA35 -> 869474.42 | EB14: =EB15+EB26+EB30+EB35 -> 869474.42 | EC14: =EC15+EC26+EC30+EC35 -> 869474.42 | ED14: =ED15+ED26+ED30+ED35 -> 869474.42 | EE14: =EE15+EE26+EE30+EE35 -> 869474.42 | ... EI14: =EI15+EI26+EI30+EI35 -> 869474.42 | EJ14: =SUM(DX14:EI14) -> 10433693
A15: 1.1. Material directo | B15: =SUM(B16:B25) -> 256030 | C15: =SUM(C16:C25) -> 256030 | D15: =SUM(D16:D25) -> 256030 | E15: =SUM(E16:E25) -> 256030 | F15: =SUM(F16:F25) -> 256030 | G15: =SUM(G16:G25) -> 256030 | H15: =SUM(H16:H25) -> 256030 | I15: =SUM(I16:I25) -> 256030 | ... M15: =SUM(M16:M25) -> 256030 | N15: =SUM(B15:M15) -> 3072360 | P15: =SUM(P16:P25) -> 282170.66 | Q15: =SUM(Q16:Q25) -> 282170.66 | R15: =SUM(R16:R25) -> 282170.66 | S15: =SUM(S16:S25) -> 282170.66 | T15: =SUM(T16:T25) -> 282170.66 | U15: =SUM(U16:U25) -> 282170.66 | V15: =SUM(V16:V25) -> 282170.66 | W15: =SUM(W16:W25) -> 282170.66 | ... AA15: =SUM(AA16:AA25) -> 282170.66 | AB15: =SUM(P15:AA15) -> 3386048 | AD15: =SUM(AD16:AD25) -> 314055.95 | AE15: =SUM(AE16:AE25) -> 314055.95 | AF15: =SUM(AF16:AF25) -> 314055.95 | AG15: =SUM(AG16:AG25) -> 314055.95 | AH15: =SUM(AH16:AH25) -> 314055.95 | AI15: =SUM(AI16:AI25) -> 314055.95 | AJ15: =SUM(AJ16:AJ25) -> 314055.95 | AK15: =SUM(AK16:AK25) -> 314055.95 | ... AO15: =SUM(AO16:AO25) -> 314055.95 | AP15: =SUM(AD15:AO15) -> 3768671.4 | AR15: =SUM(AR16:AR25) -> 349544.27 | AS15: =SUM(AS16:AS25) -> 349544.27 | AT15: =SUM(AT16:AT25) -> 349544.27 | AU15: =SUM(AU16:AU25) -> 349544.27 | AV15: =SUM(AV16:AV25) -> 349544.27 | AW15: =SUM(AW16:AW25) -> 349544.27 | AX15: =SUM(AX16:AX25) -> 349544.27 | AY15: =SUM(AY16:AY25) -> 349544.27 | ... BC15: =SUM(BC16:BC25) -> 349544.27 | BD15: =SUM(AR15:BC15) -> 4194531.2 | BF15: =SUM(BF16:BF25) -> 389042.77 | BG15: =SUM(BG16:BG25) -> 389042.77 | BH15: =SUM(BH16:BH25) -> 389042.77 | BI15: =SUM(BI16:BI25) -> 389042.77 | BJ15: =SUM(BJ16:BJ25) -> 389042.77 | BK15: =SUM(BK16:BK25) -> 389042.77 | BL15: =SUM(BL16:BL25) -> 389042.77 | BM15: =SUM(BM16:BM25) -> 389042.77 | ... BQ15: =SUM(BQ16:BQ25) -> 389042.77 | BR15: =SUM(BF15:BQ15) -> 4668513.3 | BT15: =SUM(BT16:BT25) -> 433004.61 | BU15: =SUM(BU16:BU25) -> 433004.61 | BV15: =SUM(BV16:BV25) -> 433004.61 | BW15: =SUM(BW16:BW25) -> 433004.61 | BX15: =SUM(BX16:BX25) -> 433004.61 | BY15: =SUM(BY16:BY25) -> 433004.61 | BZ15: =SUM(BZ16:BZ25) -> 433004.61 | CA15: =SUM(CA16:CA25) -> 433004.61 | ... CE15: =SUM(CE16:CE25) -> 433004.61 | CF15: =SUM(BT15:CE15) -> 5196055.3 | CH15: =SUM(CH16:CH25) -> 481934.13 | CI15: =SUM(CI16:CI25) -> 481934.13 | CJ15: =SUM(CJ16:CJ25) -> 481934.13 | CK15: =SUM(CK16:CK25) -> 481934.13 | CL15: =SUM(CL16:CL25) -> 481934.13 | CM15: =SUM(CM16:CM25) -> 481934.13 | CN15: =SUM(CN16:CN25) -> 481934.13 | CO15: =SUM(CO16:CO25) -> 481934.13 | ... CS15: =SUM(CS16:CS25) -> 481934.13 | CT15: =SUM(CH15:CS15) -> 5783209.5 | CV15: =SUM(CV16:CV25) -> 536392.68 | CW15: =SUM(CW16:CW25) -> 536392.68 | CX15: =SUM(CX16:CX25) -> 536392.68 | CY15: =SUM(CY16:CY25) -> 536392.68 | CZ15: =SUM(CZ16:CZ25) -> 536392.68 | DA15: =SUM(DA16:DA25) -> 536392.68 | DB15: =SUM(DB16:DB25) -> 536392.68 | DC15: =SUM(DC16:DC25) -> 536392.68 | ... DG15: =SUM(DG16:DG25) -> 536392.68 | DH15: =SUM(CV15:DG15) -> 6436712.2 | DJ15: =SUM(DJ16:DJ25) -> 597005.06 | DK15: =SUM(DK16:DK25) -> 597005.06 | DL15: =SUM(DL16:DL25) -> 597005.06 | DM15: =SUM(DM16:DM25) -> 597005.06 | DN15: =SUM(DN16:DN25) -> 597005.06 | DO15: =SUM(DO16:DO25) -> 597005.06 | DP15: =SUM(DP16:DP25) -> 597005.06 | DQ15: =SUM(DQ16:DQ25) -> 597005.06 | ... DU15: =SUM(DU16:DU25) -> 597005.06 | DV15: =SUM(DJ15:DU15) -> 7164060.7 | DX15: =SUM(DX16:DX25) -> 664466.63 | DY15: =SUM(DY16:DY25) -> 664466.63 | DZ15: =SUM(DZ16:DZ25) -> 664466.63 | EA15: =SUM(EA16:EA25) -> 664466.63 | EB15: =SUM(EB16:EB25) -> 664466.63 | EC15: =SUM(EC16:EC25) -> 664466.63 | ED15: =SUM(ED16:ED25) -> 664466.63 | EE15: =SUM(EE16:EE25) -> 664466.63 | ... EI15: =SUM(EI16:EI25) -> 664466.63 | EJ15: =SUM(DX15:EI15) -> 7973599.5
A16: Madera | B16: =(1.08*B7*75) -> 119880 | C16: =B16*(1+C$3) -> 119880 | D16: =C16*(1+D$3) -> 119880 | E16: =D16*(1+E$3) -> 119880 | F16: =E16*(1+F$3) -> 119880 | G16: =F16*(1+G$3) -> 119880 | H16: =G16*(1+H$3) -> 119880 | I16: =H16*(1+I$3) -> 119880 | J16: =I16*(1+J$3) -> 119880 | ... M16: =L16*(1+M$3) -> 119880 | N16: =SUM(B16:M16) -> 1438560 | O16: 1 | P16: =$O16*B16*(1+$P$3)*(1+$P$4) -> 132119.75 | Q16: =$O16*C16*(1+$P$3)*(1+$P$4) -> 132119.75 | R16: =$O16*D16*(1+$P$3)*(1+$P$4) -> 132119.75 | S16: =$O16*E16*(1+$P$3)*(1+$P$4) -> 132119.75 | T16: =$O16*F16*(1+$P$3)*(1+$P$4) -> 132119.75 | U16: =$O16*G16*(1+$P$3)*(1+$P$4) -> 132119.75 | V16: =$O16*H16*(1+$P$3)*(1+$P$4) -> 132119.75 | W16: =$O16*I16*(1+$P$3)*(1+$P$4) -> 132119.75 | ... AA16: =$O16*M16*(1+$P$3)*(1+$P$4) -> 132119.75 | AB16: =SUM(P16:AA16) -> 1585437 | AC16: 1 | AD16: =$AC16*P16*(1+$AD$3)*(1+$AD$4) -> 147049.28 | AE16: =$AC16*Q16*(1+$AD$3)*(1+$AD$4) -> 147049.28 | AF16: =$AC16*R16*(1+$AD$3)*(1+$AD$4) -> 147049.28 | AG16: =$AC16*S16*(1+$AD$3)*(1+$AD$4) -> 147049.28 | AH16: =$AC16*T16*(1+$AD$3)*(1+$AD$4) -> 147049.28 | AI16: =$AC16*U16*(1+$AD$3)*(1+$AD$4) -> 147049.28 | AJ16: =$AC16*V16*(1+$AD$3)*(1+$AD$4) -> 147049.28 | AK16: =$AC16*W16*(1+$AD$3)*(1+$AD$4) -> 147049.28 | ... AO16: =$AC16*AA16*(1+$AD$3)*(1+$AD$4) -> 147049.28 | AP16: =SUM(AD16:AO16) -> 1764591.4 | AQ16: 1 | AR16: =$AQ16*AD16*(1+$AR$3)*(1+$AR$4) -> 163665.85 | AS16: =$AQ16*AE16*(1+$AR$3)*(1+$AR$4) -> 163665.85 | AT16: =$AQ16*AF16*(1+$AR$3)*(1+$AR$4) -> 163665.85 | AU16: =$AQ16*AG16*(1+$AR$3)*(1+$AR$4) -> 163665.85 | AV16: =$AQ16*AH16*(1+$AR$3)*(1+$AR$4) -> 163665.85 | AW16: =$AQ16*AI16*(1+$AR$3)*(1+$AR$4) -> 163665.85 | AX16: =$AQ16*AJ16*(1+$AR$3)*(1+$AR$4) -> 163665.85 | AY16: =$AQ16*AK16*(1+$AR$3)*(1+$AR$4) -> 163665.85 | ... BC16: =$AQ16*AO16*(1+$AR$3)*(1+$AR$4) -> 163665.85 | BD16: =SUM(AR16:BC16) -> 1963990.2 | BE16: 1 | BF16: =$BE16*AR16*(1+$BF$3)*(1+$BF$4) -> 182160.09 | BG16: =$BE16*AS16*(1+$BF$3)*(1+$BF$4) -> 182160.09 | BH16: =$BE16*AT16*(1+$BF$3)*(1+$BF$4) -> 182160.09 | BI16: =$BE16*AU16*(1+$BF$3)*(1+$BF$4) -> 182160.09 | BJ16: =$BE16*AV16*(1+$BF$3)*(1+$BF$4) -> 182160.09 | BK16: =$BE16*AW16*(1+$BF$3)*(1+$BF$4) -> 182160.09 | BL16: =$BE16*AX16*(1+$BF$3)*(1+$BF$4) -> 182160.09 | BM16: =$BE16*AY16*(1+$BF$3)*(1+$BF$4) -> 182160.09 | ... BQ16: =$BE16*BC16*(1+$BF$3)*(1+$BF$4) -> 182160.09 | BR16: =SUM(BF16:BQ16) -> 2185921.1 | BS16: 1 | BT16: =$BS16*BF16*(1+$BT$3)*(1+$BT$4) -> 202744.18 | BU16: =$BS16*BG16*(1+$BT$3)*(1+$BT$4) -> 202744.18 | BV16: =$BS16*BH16*(1+$BT$3)*(1+$BT$4) -> 202744.18 | BW16: =$BS16*BI16*(1+$BT$3)*(1+$BT$4) -> 202744.18 | BX16: =$BS16*BJ16*(1+$BT$3)*(1+$BT$4) -> 202744.18 | BY16: =$BS16*BK16*(1+$BT$3)*(1+$BT$4) -> 202744.18 | BZ16: =$BS16*BL16*(1+$BT$3)*(1+$BT$4) -> 202744.18 | CA16: =$BS16*BM16*(1+$BT$3)*(1+$BT$4) -> 202744.18 | ... CE16: =$BS16*BQ16*(1+$BT$3)*(1+$BT$4) -> 202744.18 | CF16: =SUM(BT16:CE16) -> 2432930.1 | CG16: 1 | CH16: =$CG16*BT16*(1+$CH$3)*(1+$CH$4) -> 225654.27 | CI16: =$CG16*BU16*(1+$CH$3)*(1+$CH$4) -> 225654.27 | CJ16: =$CG16*BV16*(1+$CH$3)*(1+$CH$4) -> 225654.27 | CK16: =$CG16*BW16*(1+$CH$3)*(1+$CH$4) -> 225654.27 | CL16: =$CG16*BX16*(1+$CH$3)*(1+$CH$4) -> 225654.27 | CM16: =$CG16*BY16*(1+$CH$3)*(1+$CH$4) -> 225654.27 | CN16: =$CG16*BZ16*(1+$CH$3)*(1+$CH$4) -> 225654.27 | CO16: =$CG16*CA16*(1+$CH$3)*(1+$CH$4) -> 225654.27 | ... CS16: =$CG16*CE16*(1+$CH$3)*(1+$CH$4) -> 225654.27 | CT16: =SUM(CH16:CS16) -> 2707851.3 | CU16: 1 | CV16: =$CU16*CH16*(1+$CV$3)*(1+$CV$4) -> 251153.2 | CW16: =$CU16*CI16*(1+$CV$3)*(1+$CV$4) -> 251153.2 | CX16: =$CU16*CJ16*(1+$CV$3)*(1+$CV$4) -> 251153.2 | CY16: =$CU16*CK16*(1+$CV$3)*(1+$CV$4) -> 251153.2 | CZ16: =$CU16*CL16*(1+$CV$3)*(1+$CV$4) -> 251153.2 | DA16: =$CU16*CM16*(1+$CV$3)*(1+$CV$4) -> 251153.2 | DB16: =$CU16*CN16*(1+$CV$3)*(1+$CV$4) -> 251153.2 | DC16: =$CU16*CO16*(1+$CV$3)*(1+$CV$4) -> 251153.2 | ... DG16: =$CU16*CS16*(1+$CV$3)*(1+$CV$4) -> 251153.2 | DH16: =SUM(CV16:DG16) -> 3013838.4 | DI16: 1 | DJ16: =$DI16*CV16*(1+$DJ$3)*(1+$DJ$4) -> 279533.52 | DK16: =$DI16*CW16*(1+$DJ$3)*(1+$DJ$4) -> 279533.52 | DL16: =$DI16*CX16*(1+$DJ$3)*(1+$DJ$4) -> 279533.52 | DM16: =$DI16*CY16*(1+$DJ$3)*(1+$DJ$4) -> 279533.52 | DN16: =$DI16*CZ16*(1+$DJ$3)*(1+$DJ$4) -> 279533.52 | DO16: =$DI16*DA16*(1+$DJ$3)*(1+$DJ$4) -> 279533.52 | DP16: =$DI16*DB16*(1+$DJ$3)*(1+$DJ$4) -> 279533.52 | DQ16: =$DI16*DC16*(1+$DJ$3)*(1+$DJ$4) -> 279533.52 | ... DU16: =$DI16*DG16*(1+$DJ$3)*(1+$DJ$4) -> 279533.52 | DV16: =SUM(DJ16:DU16) -> 3354402.2 | DW16: 1 | DX16: =$DW16*DJ16*(1+$DX$3)*(1+$DX$4) -> 311120.8 | DY16: =$DW16*DK16*(1+$DX$3)*(1+$DX$4) -> 311120.8 | DZ16: =$DW16*DL16*(1+$DX$3)*(1+$DX$4) -> 311120.8 | EA16: =$DW16*DM16*(1+$DX$3)*(1+$DX$4) -> 311120.8 | EB16: =$DW16*DN16*(1+$DX$3)*(1+$DX$4) -> 311120.8 | EC16: =$DW16*DO16*(1+$DX$3)*(1+$DX$4) -> 311120.8 | ED16: =$DW16*DP16*(1+$DX$3)*(1+$DX$4) -> 311120.8 | EE16: =$DW16*DQ16*(1+$DX$3)*(1+$DX$4) -> 311120.8 | ... EI16: =$DW16*DU16*(1+$DX$3)*(1+$DX$4) -> 311120.8 | EJ16: =SUM(DX16:EI16) -> 3733449.6
A17: MDF | B17: =B7*100*0.9 -> 133200 | C17: =B17*(1+C$3) -> 133200 | D17: =C17*(1+D$3) -> 133200 | E17: =D17*(1+E$3) -> 133200 | F17: =E17*(1+F$3) -> 133200 | G17: =F17*(1+G$3) -> 133200 | H17: =G17*(1+H$3) -> 133200 | I17: =H17*(1+I$3) -> 133200 | J17: =I17*(1+J$3) -> 133200 | ... M17: =L17*(1+M$3) -> 133200 | N17: =SUM(B17:M17) -> 1598400 | O17: 1 | P17: =$O17*B17*(1+$P$3)*(1+$P$4) -> 146799.72 | Q17: =$O17*C17*(1+$P$3)*(1+$P$4) -> 146799.72 | R17: =$O17*D17*(1+$P$3)*(1+$P$4) -> 146799.72 | S17: =$O17*E17*(1+$P$3)*(1+$P$4) -> 146799.72 | T17: =$O17*F17*(1+$P$3)*(1+$P$4) -> 146799.72 | U17: =$O17*G17*(1+$P$3)*(1+$P$4) -> 146799.72 | V17: =$O17*H17*(1+$P$3)*(1+$P$4) -> 146799.72 | W17: =$O17*I17*(1+$P$3)*(1+$P$4) -> 146799.72 | ... AA17: =$O17*M17*(1+$P$3)*(1+$P$4) -> 146799.72 | AB17: =SUM(P17:AA17) -> 1761596.6 | AC17: 1 | AD17: =$AC17*P17*(1+$AD$3)*(1+$AD$4) -> 163388.09 | AE17: =$AC17*Q17*(1+$AD$3)*(1+$AD$4) -> 163388.09 | AF17: =$AC17*R17*(1+$AD$3)*(1+$AD$4) -> 163388.09 | AG17: =$AC17*S17*(1+$AD$3)*(1+$AD$4) -> 163388.09 | AH17: =$AC17*T17*(1+$AD$3)*(1+$AD$4) -> 163388.09 | AI17: =$AC17*U17*(1+$AD$3)*(1+$AD$4) -> 163388.09 | AJ17: =$AC17*V17*(1+$AD$3)*(1+$AD$4) -> 163388.09 | AK17: =$AC17*W17*(1+$AD$3)*(1+$AD$4) -> 163388.09 | ... AO17: =$AC17*AA17*(1+$AD$3)*(1+$AD$4) -> 163388.09 | AP17: =SUM(AD17:AO17) -> 1960657.1 | AQ17: 1 | AR17: =$AQ17*AD17*(1+$AR$3)*(1+$AR$4) -> 181850.94 | AS17: =$AQ17*AE17*(1+$AR$3)*(1+$AR$4) -> 181850.94 | AT17: =$AQ17*AF17*(1+$AR$3)*(1+$AR$4) -> 181850.94 | AU17: =$AQ17*AG17*(1+$AR$3)*(1+$AR$4) -> 181850.94 | AV17: =$AQ17*AH17*(1+$AR$3)*(1+$AR$4) -> 181850.94 | AW17: =$AQ17*AI17*(1+$AR$3)*(1+$AR$4) -> 181850.94 | AX17: =$AQ17*AJ17*(1+$AR$3)*(1+$AR$4) -> 181850.94 | AY17: =$AQ17*AK17*(1+$AR$3)*(1+$AR$4) -> 181850.94 | ... BC17: =$AQ17*AO17*(1+$AR$3)*(1+$AR$4) -> 181850.94 | BD17: =SUM(AR17:BC17) -> 2182211.3 | BE17: 1 | BF17: =$BE17*AR17*(1+$BF$3)*(1+$BF$4) -> 202400.1 | BG17: =$BE17*AS17*(1+$BF$3)*(1+$BF$4) -> 202400.1 | BH17: =$BE17*AT17*(1+$BF$3)*(1+$BF$4) -> 202400.1 | BI17: =$BE17*AU17*(1+$BF$3)*(1+$BF$4) -> 202400.1 | BJ17: =$BE17*AV17*(1+$BF$3)*(1+$BF$4) -> 202400.1 | BK17: =$BE17*AW17*(1+$BF$3)*(1+$BF$4) -> 202400.1 | BL17: =$BE17*AX17*(1+$BF$3)*(1+$BF$4) -> 202400.1 | BM17: =$BE17*AY17*(1+$BF$3)*(1+$BF$4) -> 202400.1 | ... BQ17: =$BE17*BC17*(1+$BF$3)*(1+$BF$4) -> 202400.1 | BR17: =SUM(BF17:BQ17) -> 2428801.2 | BS17: 1 | BT17: =$BS17*BF17*(1+$BT$3)*(1+$BT$4) -> 225271.31 | BU17: =$BS17*BG17*(1+$BT$3)*(1+$BT$4) -> 225271.31 | BV17: =$BS17*BH17*(1+$BT$3)*(1+$BT$4) -> 225271.31 | BW17: =$BS17*BI17*(1+$BT$3)*(1+$BT$4) -> 225271.31 | BX17: =$BS17*BJ17*(1+$BT$3)*(1+$BT$4) -> 225271.31 | BY17: =$BS17*BK17*(1+$BT$3)*(1+$BT$4) -> 225271.31 | BZ17: =$BS17*BL17*(1+$BT$3)*(1+$BT$4) -> 225271.31 | CA17: =$BS17*BM17*(1+$BT$3)*(1+$BT$4) -> 225271.31 | ... CE17: =$BS17*BQ17*(1+$BT$3)*(1+$BT$4) -> 225271.31 | CF17: =SUM(BT17:CE17) -> 2703255.7 | CG17: 1 | CH17: =$CG17*BT17*(1+$CH$3)*(1+$CH$4) -> 250726.97 | CI17: =$CG17*BU17*(1+$CH$3)*(1+$CH$4) -> 250726.97 | CJ17: =$CG17*BV17*(1+$CH$3)*(1+$CH$4) -> 250726.97 | CK17: =$CG17*BW17*(1+$CH$3)*(1+$CH$4) -> 250726.97 | CL17: =$CG17*BX17*(1+$CH$3)*(1+$CH$4) -> 250726.97 | CM17: =$CG17*BY17*(1+$CH$3)*(1+$CH$4) -> 250726.97 | CN17: =$CG17*BZ17*(1+$CH$3)*(1+$CH$4) -> 250726.97 | CO17: =$CG17*CA17*(1+$CH$3)*(1+$CH$4) -> 250726.97 | ... CS17: =$CG17*CE17*(1+$CH$3)*(1+$CH$4) -> 250726.97 | CT17: =SUM(CH17:CS17) -> 3008723.6 | CU17: 1 | CV17: =$CU17*CH17*(1+$CV$3)*(1+$CV$4) -> 279059.12 | CW17: =$CU17*CI17*(1+$CV$3)*(1+$CV$4) -> 279059.12 | CX17: =$CU17*CJ17*(1+$CV$3)*(1+$CV$4) -> 279059.12 | CY17: =$CU17*CK17*(1+$CV$3)*(1+$CV$4) -> 279059.12 | CZ17: =$CU17*CL17*(1+$CV$3)*(1+$CV$4) -> 279059.12 | DA17: =$CU17*CM17*(1+$CV$3)*(1+$CV$4) -> 279059.12 | DB17: =$CU17*CN17*(1+$CV$3)*(1+$CV$4) -> 279059.12 | DC17: =$CU17*CO17*(1+$CV$3)*(1+$CV$4) -> 279059.12 | ... DG17: =$CU17*CS17*(1+$CV$3)*(1+$CV$4) -> 279059.12 | DH17: =SUM(CV17:DG17) -> 3348709.4 | DI17: 1 | DJ17: =$DI17*CV17*(1+$DJ$3)*(1+$DJ$4) -> 310592.8 | DK17: =$DI17*CW17*(1+$DJ$3)*(1+$DJ$4) -> 310592.8 | DL17: =$DI17*CX17*(1+$DJ$3)*(1+$DJ$4) -> 310592.8 | DM17: =$DI17*CY17*(1+$DJ$3)*(1+$DJ$4) -> 310592.8 | DN17: =$DI17*CZ17*(1+$DJ$3)*(1+$DJ$4) -> 310592.8 | DO17: =$DI17*DA17*(1+$DJ$3)*(1+$DJ$4) -> 310592.8 | DP17: =$DI17*DB17*(1+$DJ$3)*(1+$DJ$4) -> 310592.8 | DQ17: =$DI17*DC17*(1+$DJ$3)*(1+$DJ$4) -> 310592.8 | ... DU17: =$DI17*DG17*(1+$DJ$3)*(1+$DJ$4) -> 310592.8 | DV17: =SUM(DJ17:DU17) -> 3727113.5 | DW17: 1 | DX17: =$DW17*DJ17*(1+$DX$3)*(1+$DX$4) -> 345689.78 | DY17: =$DW17*DK17*(1+$DX$3)*(1+$DX$4) -> 345689.78 | DZ17: =$DW17*DL17*(1+$DX$3)*(1+$DX$4) -> 345689.78 | EA17: =$DW17*DM17*(1+$DX$3)*(1+$DX$4) -> 345689.78 | EB17: =$DW17*DN17*(1+$DX$3)*(1+$DX$4) -> 345689.78 | EC17: =$DW17*DO17*(1+$DX$3)*(1+$DX$4) -> 345689.78 | ED17: =$DW17*DP17*(1+$DX$3)*(1+$DX$4) -> 345689.78 | EE17: =$DW17*DQ17*(1+$DX$3)*(1+$DX$4) -> 345689.78 | ... EI17: =$DW17*DU17*(1+$DX$3)*(1+$DX$4) -> 345689.78 | EJ17: =SUM(DX17:EI17) -> 4148277.4
A18: Pegamento para madera | B18: 800 | C18: =B18*(1+C$3) -> 800 | D18: =C18*(1+D$3) -> 800 | E18: =D18*(1+E$3) -> 800 | F18: =E18*(1+F$3) -> 800 | G18: =F18*(1+G$3) -> 800 | H18: =G18*(1+H$3) -> 800 | I18: =H18*(1+I$3) -> 800 | J18: =I18*(1+J$3) -> 800 | ... M18: =L18*(1+M$3) -> 800 | N18: =SUM(B18:M18) -> 9600 | O18: 1 | P18: =$O18*B18*(1+$P$3)*(1+$P$4) -> 881.68 | Q18: =$O18*C18*(1+$P$3)*(1+$P$4) -> 881.68 | R18: =$O18*D18*(1+$P$3)*(1+$P$4) -> 881.68 | S18: =$O18*E18*(1+$P$3)*(1+$P$4) -> 881.68 | T18: =$O18*F18*(1+$P$3)*(1+$P$4) -> 881.68 | U18: =$O18*G18*(1+$P$3)*(1+$P$4) -> 881.68 | V18: =$O18*H18*(1+$P$3)*(1+$P$4) -> 881.68 | W18: =$O18*I18*(1+$P$3)*(1+$P$4) -> 881.68 | ... AA18: =$O18*M18*(1+$P$3)*(1+$P$4) -> 881.68 | AB18: =SUM(P18:AA18) -> 10580.16 | AC18: 1 | AD18: =$AC18*P18*(1+$AD$3)*(1+$AD$4) -> 981.30984 | AE18: =$AC18*Q18*(1+$AD$3)*(1+$AD$4) -> 981.30984 | AF18: =$AC18*R18*(1+$AD$3)*(1+$AD$4) -> 981.30984 | AG18: =$AC18*S18*(1+$AD$3)*(1+$AD$4) -> 981.30984 | AH18: =$AC18*T18*(1+$AD$3)*(1+$AD$4) -> 981.30984 | AI18: =$AC18*U18*(1+$AD$3)*(1+$AD$4) -> 981.30984 | AJ18: =$AC18*V18*(1+$AD$3)*(1+$AD$4) -> 981.30984 | AK18: =$AC18*W18*(1+$AD$3)*(1+$AD$4) -> 981.30984 | ... AO18: =$AC18*AA18*(1+$AD$3)*(1+$AD$4) -> 981.30984 | AP18: =SUM(AD18:AO18) -> 11775.718 | AQ18: 1 | AR18: =$AQ18*AD18*(1+$AR$3)*(1+$AR$4) -> 1092.1979 | AS18: =$AQ18*AE18*(1+$AR$3)*(1+$AR$4) -> 1092.1979 | AT18: =$AQ18*AF18*(1+$AR$3)*(1+$AR$4) -> 1092.1979 | AU18: =$AQ18*AG18*(1+$AR$3)*(1+$AR$4) -> 1092.1979 | AV18: =$AQ18*AH18*(1+$AR$3)*(1+$AR$4) -> 1092.1979 | AW18: =$AQ18*AI18*(1+$AR$3)*(1+$AR$4) -> 1092.1979 | AX18: =$AQ18*AJ18*(1+$AR$3)*(1+$AR$4) -> 1092.1979 | AY18: =$AQ18*AK18*(1+$AR$3)*(1+$AR$4) -> 1092.1979 | ... BC18: =$AQ18*AO18*(1+$AR$3)*(1+$AR$4) -> 1092.1979 | BD18: =SUM(AR18:BC18) -> 13106.374 | BE18: 1 | BF18: =$BE18*AR18*(1+$BF$3)*(1+$BF$4) -> 1215.6162 | BG18: =$BE18*AS18*(1+$BF$3)*(1+$BF$4) -> 1215.6162 | BH18: =$BE18*AT18*(1+$BF$3)*(1+$BF$4) -> 1215.6162 | BI18: =$BE18*AU18*(1+$BF$3)*(1+$BF$4) -> 1215.6162 | BJ18: =$BE18*AV18*(1+$BF$3)*(1+$BF$4) -> 1215.6162 | BK18: =$BE18*AW18*(1+$BF$3)*(1+$BF$4) -> 1215.6162 | BL18: =$BE18*AX18*(1+$BF$3)*(1+$BF$4) -> 1215.6162 | BM18: =$BE18*AY18*(1+$BF$3)*(1+$BF$4) -> 1215.6162 | ... BQ18: =$BE18*BC18*(1+$BF$3)*(1+$BF$4) -> 1215.6162 | BR18: =SUM(BF18:BQ18) -> 14587.395 | BS18: 1 | BT18: =$BS18*BF18*(1+$BT$3)*(1+$BT$4) -> 1352.9808 | BU18: =$BS18*BG18*(1+$BT$3)*(1+$BT$4) -> 1352.9808 | BV18: =$BS18*BH18*(1+$BT$3)*(1+$BT$4) -> 1352.9808 | BW18: =$BS18*BI18*(1+$BT$3)*(1+$BT$4) -> 1352.9808 | BX18: =$BS18*BJ18*(1+$BT$3)*(1+$BT$4) -> 1352.9808 | BY18: =$BS18*BK18*(1+$BT$3)*(1+$BT$4) -> 1352.9808 | BZ18: =$BS18*BL18*(1+$BT$3)*(1+$BT$4) -> 1352.9808 | CA18: =$BS18*BM18*(1+$BT$3)*(1+$BT$4) -> 1352.9808 | ... CE18: =$BS18*BQ18*(1+$BT$3)*(1+$BT$4) -> 1352.9808 | CF18: =SUM(BT18:CE18) -> 16235.77 | CG18: 1 | CH18: =$CG18*BT18*(1+$CH$3)*(1+$CH$4) -> 1505.8677 | CI18: =$CG18*BU18*(1+$CH$3)*(1+$CH$4) -> 1505.8677 | CJ18: =$CG18*BV18*(1+$CH$3)*(1+$CH$4) -> 1505.8677 | CK18: =$CG18*BW18*(1+$CH$3)*(1+$CH$4) -> 1505.8677 | CL18: =$CG18*BX18*(1+$CH$3)*(1+$CH$4) -> 1505.8677 | CM18: =$CG18*BY18*(1+$CH$3)*(1+$CH$4) -> 1505.8677 | CN18: =$CG18*BZ18*(1+$CH$3)*(1+$CH$4) -> 1505.8677 | CO18: =$CG18*CA18*(1+$CH$3)*(1+$CH$4) -> 1505.8677 | ... CS18: =$CG18*CE18*(1+$CH$3)*(1+$CH$4) -> 1505.8677 | CT18: =SUM(CH18:CS18) -> 18070.412 | CU18: 1 | CV18: =$CU18*CH18*(1+$CV$3)*(1+$CV$4) -> 1676.0307 | CW18: =$CU18*CI18*(1+$CV$3)*(1+$CV$4) -> 1676.0307 | CX18: =$CU18*CJ18*(1+$CV$3)*(1+$CV$4) -> 1676.0307 | CY18: =$CU18*CK18*(1+$CV$3)*(1+$CV$4) -> 1676.0307 | CZ18: =$CU18*CL18*(1+$CV$3)*(1+$CV$4) -> 1676.0307 | DA18: =$CU18*CM18*(1+$CV$3)*(1+$CV$4) -> 1676.0307 | DB18: =$CU18*CN18*(1+$CV$3)*(1+$CV$4) -> 1676.0307 | DC18: =$CU18*CO18*(1+$CV$3)*(1+$CV$4) -> 1676.0307 | ... DG18: =$CU18*CS18*(1+$CV$3)*(1+$CV$4) -> 1676.0307 | DH18: =SUM(CV18:DG18) -> 20112.369 | DI18: 1 | DJ18: =$DI18*CV18*(1+$DJ$3)*(1+$DJ$4) -> 1865.4222 | DK18: =$DI18*CW18*(1+$DJ$3)*(1+$DJ$4) -> 1865.4222 | DL18: =$DI18*CX18*(1+$DJ$3)*(1+$DJ$4) -> 1865.4222 | DM18: =$DI18*CY18*(1+$DJ$3)*(1+$DJ$4) -> 1865.4222 | DN18: =$DI18*CZ18*(1+$DJ$3)*(1+$DJ$4) -> 1865.4222 | DO18: =$DI18*DA18*(1+$DJ$3)*(1+$DJ$4) -> 1865.4222 | DP18: =$DI18*DB18*(1+$DJ$3)*(1+$DJ$4) -> 1865.4222 | DQ18: =$DI18*DC18*(1+$DJ$3)*(1+$DJ$4) -> 1865.4222 | ... DU18: =$DI18*DG18*(1+$DJ$3)*(1+$DJ$4) -> 1865.4222 | DV18: =SUM(DJ18:DU18) -> 22385.066 | DW18: 1 | DX18: =$DW18*DJ18*(1+$DX$3)*(1+$DX$4) -> 2076.2149 | DY18: =$DW18*DK18*(1+$DX$3)*(1+$DX$4) -> 2076.2149 | DZ18: =$DW18*DL18*(1+$DX$3)*(1+$DX$4) -> 2076.2149 | EA18: =$DW18*DM18*(1+$DX$3)*(1+$DX$4) -> 2076.2149 | EB18: =$DW18*DN18*(1+$DX$3)*(1+$DX$4) -> 2076.2149 | EC18: =$DW18*DO18*(1+$DX$3)*(1+$DX$4) -> 2076.2149 | ED18: =$DW18*DP18*(1+$DX$3)*(1+$DX$4) -> 2076.2149 | EE18: =$DW18*DQ18*(1+$DX$3)*(1+$DX$4) -> 2076.2149 | ... EI18: =$DW18*DU18*(1+$DX$3)*(1+$DX$4) -> 2076.2149 | EJ18: =SUM(DX18:EI18) -> 24914.579
A19: Clavos | B19: 150 | C19: =B19*(1+C$3) -> 150 | D19: =C19*(1+D$3) -> 150 | E19: =D19*(1+E$3) -> 150 | F19: =E19*(1+F$3) -> 150 | G19: =F19*(1+G$3) -> 150 | H19: =G19*(1+H$3) -> 150 | I19: =H19*(1+I$3) -> 150 | J19: =I19*(1+J$3) -> 150 | ... M19: =L19*(1+M$3) -> 150 | N19: =SUM(B19:M19) -> 1800 | O19: 1 | P19: =$O19*B19*(1+$P$3)*(1+$P$4) -> 165.315 | Q19: =$O19*C19*(1+$P$3)*(1+$P$4) -> 165.315 | R19: =$O19*D19*(1+$P$3)*(1+$P$4) -> 165.315 | S19: =$O19*E19*(1+$P$3)*(1+$P$4) -> 165.315 | T19: =$O19*F19*(1+$P$3)*(1+$P$4) -> 165.315 | U19: =$O19*G19*(1+$P$3)*(1+$P$4) -> 165.315 | V19: =$O19*H19*(1+$P$3)*(1+$P$4) -> 165.315 | W19: =$O19*I19*(1+$P$3)*(1+$P$4) -> 165.315 | ... AA19: =$O19*M19*(1+$P$3)*(1+$P$4) -> 165.315 | AB19: =SUM(P19:AA19) -> 1983.78 | AC19: 1 | AD19: =$AC19*P19*(1+$AD$3)*(1+$AD$4) -> 183.9956 | AE19: =$AC19*Q19*(1+$AD$3)*(1+$AD$4) -> 183.9956 | AF19: =$AC19*R19*(1+$AD$3)*(1+$AD$4) -> 183.9956 | AG19: =$AC19*S19*(1+$AD$3)*(1+$AD$4) -> 183.9956 | AH19: =$AC19*T19*(1+$AD$3)*(1+$AD$4) -> 183.9956 | AI19: =$AC19*U19*(1+$AD$3)*(1+$AD$4) -> 183.9956 | AJ19: =$AC19*V19*(1+$AD$3)*(1+$AD$4) -> 183.9956 | AK19: =$AC19*W19*(1+$AD$3)*(1+$AD$4) -> 183.9956 | ... AO19: =$AC19*AA19*(1+$AD$3)*(1+$AD$4) -> 183.9956 | AP19: =SUM(AD19:AO19) -> 2207.9471 | AQ19: 1 | AR19: =$AQ19*AD19*(1+$AR$3)*(1+$AR$4) -> 204.7871 | AS19: =$AQ19*AE19*(1+$AR$3)*(1+$AR$4) -> 204.7871 | AT19: =$AQ19*AF19*(1+$AR$3)*(1+$AR$4) -> 204.7871 | AU19: =$AQ19*AG19*(1+$AR$3)*(1+$AR$4) -> 204.7871 | AV19: =$AQ19*AH19*(1+$AR$3)*(1+$AR$4) -> 204.7871 | AW19: =$AQ19*AI19*(1+$AR$3)*(1+$AR$4) -> 204.7871 | AX19: =$AQ19*AJ19*(1+$AR$3)*(1+$AR$4) -> 204.7871 | AY19: =$AQ19*AK19*(1+$AR$3)*(1+$AR$4) -> 204.7871 | ... BC19: =$AQ19*AO19*(1+$AR$3)*(1+$AR$4) -> 204.7871 | BD19: =SUM(AR19:BC19) -> 2457.4452 | BE19: 1 | BF19: =$BE19*AR19*(1+$BF$3)*(1+$BF$4) -> 227.92804 | BG19: =$BE19*AS19*(1+$BF$3)*(1+$BF$4) -> 227.92804 | BH19: =$BE19*AT19*(1+$BF$3)*(1+$BF$4) -> 227.92804 | BI19: =$BE19*AU19*(1+$BF$3)*(1+$BF$4) -> 227.92804 | BJ19: =$BE19*AV19*(1+$BF$3)*(1+$BF$4) -> 227.92804 | BK19: =$BE19*AW19*(1+$BF$3)*(1+$BF$4) -> 227.92804 | BL19: =$BE19*AX19*(1+$BF$3)*(1+$BF$4) -> 227.92804 | BM19: =$BE19*AY19*(1+$BF$3)*(1+$BF$4) -> 227.92804 | ... BQ19: =$BE19*BC19*(1+$BF$3)*(1+$BF$4) -> 227.92804 | BR19: =SUM(BF19:BQ19) -> 2735.1365 | BS19: 1 | BT19: =$BS19*BF19*(1+$BT$3)*(1+$BT$4) -> 253.68391 | BU19: =$BS19*BG19*(1+$BT$3)*(1+$BT$4) -> 253.68391 | BV19: =$BS19*BH19*(1+$BT$3)*(1+$BT$4) -> 253.68391 | BW19: =$BS19*BI19*(1+$BT$3)*(1+$BT$4) -> 253.68391 | BX19: =$BS19*BJ19*(1+$BT$3)*(1+$BT$4) -> 253.68391 | BY19: =$BS19*BK19*(1+$BT$3)*(1+$BT$4) -> 253.68391 | BZ19: =$BS19*BL19*(1+$BT$3)*(1+$BT$4) -> 253.68391 | CA19: =$BS19*BM19*(1+$BT$3)*(1+$BT$4) -> 253.68391 | ... CE19: =$BS19*BQ19*(1+$BT$3)*(1+$BT$4) -> 253.68391 | CF19: =SUM(BT19:CE19) -> 3044.2069 | CG19: 1 | CH19: =$CG19*BT19*(1+$CH$3)*(1+$CH$4) -> 282.35019 | CI19: =$CG19*BU19*(1+$CH$3)*(1+$CH$4) -> 282.35019 | CJ19: =$CG19*BV19*(1+$CH$3)*(1+$CH$4) -> 282.35019 | CK19: =$CG19*BW19*(1+$CH$3)*(1+$CH$4) -> 282.35019 | CL19: =$CG19*BX19*(1+$CH$3)*(1+$CH$4) -> 282.35019 | CM19: =$CG19*BY19*(1+$CH$3)*(1+$CH$4) -> 282.35019 | CN19: =$CG19*BZ19*(1+$CH$3)*(1+$CH$4) -> 282.35019 | CO19: =$CG19*CA19*(1+$CH$3)*(1+$CH$4) -> 282.35019 | ... CS19: =$CG19*CE19*(1+$CH$3)*(1+$CH$4) -> 282.35019 | CT19: =SUM(CH19:CS19) -> 3388.2023 | CU19: 1 | CV19: =$CU19*CH19*(1+$CV$3)*(1+$CV$4) -> 314.25576 | CW19: =$CU19*CI19*(1+$CV$3)*(1+$CV$4) -> 314.25576 | CX19: =$CU19*CJ19*(1+$CV$3)*(1+$CV$4) -> 314.25576 | CY19: =$CU19*CK19*(1+$CV$3)*(1+$CV$4) -> 314.25576 | CZ19: =$CU19*CL19*(1+$CV$3)*(1+$CV$4) -> 314.25576 | DA19: =$CU19*CM19*(1+$CV$3)*(1+$CV$4) -> 314.25576 | DB19: =$CU19*CN19*(1+$CV$3)*(1+$CV$4) -> 314.25576 | DC19: =$CU19*CO19*(1+$CV$3)*(1+$CV$4) -> 314.25576 | ... DG19: =$CU19*CS19*(1+$CV$3)*(1+$CV$4) -> 314.25576 | DH19: =SUM(CV19:DG19) -> 3771.0691 | DI19: 1 | DJ19: =$DI19*CV19*(1+$DJ$3)*(1+$DJ$4) -> 349.76666 | DK19: =$DI19*CW19*(1+$DJ$3)*(1+$DJ$4) -> 349.76666 | DL19: =$DI19*CX19*(1+$DJ$3)*(1+$DJ$4) -> 349.76666 | DM19: =$DI19*CY19*(1+$DJ$3)*(1+$DJ$4) -> 349.76666 | DN19: =$DI19*CZ19*(1+$DJ$3)*(1+$DJ$4) -> 349.76666 | DO19: =$DI19*DA19*(1+$DJ$3)*(1+$DJ$4) -> 349.76666 | DP19: =$DI19*DB19*(1+$DJ$3)*(1+$DJ$4) -> 349.76666 | DQ19: =$DI19*DC19*(1+$DJ$3)*(1+$DJ$4) -> 349.76666 | ... DU19: =$DI19*DG19*(1+$DJ$3)*(1+$DJ$4) -> 349.76666 | DV19: =SUM(DJ19:DU19) -> 4197.1999 | DW19: 1 | DX19: =$DW19*DJ19*(1+$DX$3)*(1+$DX$4) -> 389.29029 | DY19: =$DW19*DK19*(1+$DX$3)*(1+$DX$4) -> 389.29029 | DZ19: =$DW19*DL19*(1+$DX$3)*(1+$DX$4) -> 389.29029 | EA19: =$DW19*DM19*(1+$DX$3)*(1+$DX$4) -> 389.29029 | EB19: =$DW19*DN19*(1+$DX$3)*(1+$DX$4) -> 389.29029 | EC19: =$DW19*DO19*(1+$DX$3)*(1+$DX$4) -> 389.29029 | ED19: =$DW19*DP19*(1+$DX$3)*(1+$DX$4) -> 389.29029 | EE19: =$DW19*DQ19*(1+$DX$3)*(1+$DX$4) -> 389.29029 | ... EI19: =$DW19*DU19*(1+$DX$3)*(1+$DX$4) -> 389.29029 | EJ19: =SUM(DX19:EI19) -> 4671.4835
A20: Grapas | B20: 120 | C20: =B20*(1+C$3) -> 120 | D20: =C20*(1+D$3) -> 120 | E20: =D20*(1+E$3) -> 120 | F20: =E20*(1+F$3) -> 120 | G20: =F20*(1+G$3) -> 120 | H20: =G20*(1+H$3) -> 120 | I20: =H20*(1+I$3) -> 120 | J20: =I20*(1+J$3) -> 120 | ... M20: =L20*(1+M$3) -> 120 | N20: =SUM(B20:M20) -> 1440 | O20: 1 | P20: =$O20*B20*(1+$P$3)*(1+$P$4) -> 132.252 | Q20: =$O20*C20*(1+$P$3)*(1+$P$4) -> 132.252 | R20: =$O20*D20*(1+$P$3)*(1+$P$4) -> 132.252 | S20: =$O20*E20*(1+$P$3)*(1+$P$4) -> 132.252 | T20: =$O20*F20*(1+$P$3)*(1+$P$4) -> 132.252 | U20: =$O20*G20*(1+$P$3)*(1+$P$4) -> 132.252 | V20: =$O20*H20*(1+$P$3)*(1+$P$4) -> 132.252 | W20: =$O20*I20*(1+$P$3)*(1+$P$4) -> 132.252 | ... AA20: =$O20*M20*(1+$P$3)*(1+$P$4) -> 132.252 | AB20: =SUM(P20:AA20) -> 1587.024 | AC20: 1 | AD20: =$AC20*P20*(1+$AD$3)*(1+$AD$4) -> 147.19648 | AE20: =$AC20*Q20*(1+$AD$3)*(1+$AD$4) -> 147.19648 | AF20: =$AC20*R20*(1+$AD$3)*(1+$AD$4) -> 147.19648 | AG20: =$AC20*S20*(1+$AD$3)*(1+$AD$4) -> 147.19648 | AH20: =$AC20*T20*(1+$AD$3)*(1+$AD$4) -> 147.19648 | AI20: =$AC20*U20*(1+$AD$3)*(1+$AD$4) -> 147.19648 | AJ20: =$AC20*V20*(1+$AD$3)*(1+$AD$4) -> 147.19648 | AK20: =$AC20*W20*(1+$AD$3)*(1+$AD$4) -> 147.19648 | ... AO20: =$AC20*AA20*(1+$AD$3)*(1+$AD$4) -> 147.19648 | AP20: =SUM(AD20:AO20) -> 1766.3577 | AQ20: 1 | AR20: =$AQ20*AD20*(1+$AR$3)*(1+$AR$4) -> 163.82968 | AS20: =$AQ20*AE20*(1+$AR$3)*(1+$AR$4) -> 163.82968 | AT20: =$AQ20*AF20*(1+$AR$3)*(1+$AR$4) -> 163.82968 | AU20: =$AQ20*AG20*(1+$AR$3)*(1+$AR$4) -> 163.82968 | AV20: =$AQ20*AH20*(1+$AR$3)*(1+$AR$4) -> 163.82968 | AW20: =$AQ20*AI20*(1+$AR$3)*(1+$AR$4) -> 163.82968 | AX20: =$AQ20*AJ20*(1+$AR$3)*(1+$AR$4) -> 163.82968 | AY20: =$AQ20*AK20*(1+$AR$3)*(1+$AR$4) -> 163.82968 | ... BC20: =$AQ20*AO20*(1+$AR$3)*(1+$AR$4) -> 163.82968 | BD20: =SUM(AR20:BC20) -> 1965.9561 | BE20: 1 | BF20: =$BE20*AR20*(1+$BF$3)*(1+$BF$4) -> 182.34243 | BG20: =$BE20*AS20*(1+$BF$3)*(1+$BF$4) -> 182.34243 | BH20: =$BE20*AT20*(1+$BF$3)*(1+$BF$4) -> 182.34243 | BI20: =$BE20*AU20*(1+$BF$3)*(1+$BF$4) -> 182.34243 | BJ20: =$BE20*AV20*(1+$BF$3)*(1+$BF$4) -> 182.34243 | BK20: =$BE20*AW20*(1+$BF$3)*(1+$BF$4) -> 182.34243 | BL20: =$BE20*AX20*(1+$BF$3)*(1+$BF$4) -> 182.34243 | BM20: =$BE20*AY20*(1+$BF$3)*(1+$BF$4) -> 182.34243 | ... BQ20: =$BE20*BC20*(1+$BF$3)*(1+$BF$4) -> 182.34243 | BR20: =SUM(BF20:BQ20) -> 2188.1092 | BS20: 1 | BT20: =$BS20*BF20*(1+$BT$3)*(1+$BT$4) -> 202.94713 | BU20: =$BS20*BG20*(1+$BT$3)*(1+$BT$4) -> 202.94713 | BV20: =$BS20*BH20*(1+$BT$3)*(1+$BT$4) -> 202.94713 | BW20: =$BS20*BI20*(1+$BT$3)*(1+$BT$4) -> 202.94713 | BX20: =$BS20*BJ20*(1+$BT$3)*(1+$BT$4) -> 202.94713 | BY20: =$BS20*BK20*(1+$BT$3)*(1+$BT$4) -> 202.94713 | BZ20: =$BS20*BL20*(1+$BT$3)*(1+$BT$4) -> 202.94713 | CA20: =$BS20*BM20*(1+$BT$3)*(1+$BT$4) -> 202.94713 | ... CE20: =$BS20*BQ20*(1+$BT$3)*(1+$BT$4) -> 202.94713 | CF20: =SUM(BT20:CE20) -> 2435.3655 | CG20: 1 | CH20: =$CG20*BT20*(1+$CH$3)*(1+$CH$4) -> 225.88015 | CI20: =$CG20*BU20*(1+$CH$3)*(1+$CH$4) -> 225.88015 | CJ20: =$CG20*BV20*(1+$CH$3)*(1+$CH$4) -> 225.88015 | CK20: =$CG20*BW20*(1+$CH$3)*(1+$CH$4) -> 225.88015 | CL20: =$CG20*BX20*(1+$CH$3)*(1+$CH$4) -> 225.88015 | CM20: =$CG20*BY20*(1+$CH$3)*(1+$CH$4) -> 225.88015 | CN20: =$CG20*BZ20*(1+$CH$3)*(1+$CH$4) -> 225.88015 | CO20: =$CG20*CA20*(1+$CH$3)*(1+$CH$4) -> 225.88015 | ... CS20: =$CG20*CE20*(1+$CH$3)*(1+$CH$4) -> 225.88015 | CT20: =SUM(CH20:CS20) -> 2710.5618 | CU20: 1 | CV20: =$CU20*CH20*(1+$CV$3)*(1+$CV$4) -> 251.40461 | CW20: =$CU20*CI20*(1+$CV$3)*(1+$CV$4) -> 251.40461 | CX20: =$CU20*CJ20*(1+$CV$3)*(1+$CV$4) -> 251.40461 | CY20: =$CU20*CK20*(1+$CV$3)*(1+$CV$4) -> 251.40461 | CZ20: =$CU20*CL20*(1+$CV$3)*(1+$CV$4) -> 251.40461 | DA20: =$CU20*CM20*(1+$CV$3)*(1+$CV$4) -> 251.40461 | DB20: =$CU20*CN20*(1+$CV$3)*(1+$CV$4) -> 251.40461 | DC20: =$CU20*CO20*(1+$CV$3)*(1+$CV$4) -> 251.40461 | ... DG20: =$CU20*CS20*(1+$CV$3)*(1+$CV$4) -> 251.40461 | DH20: =SUM(CV20:DG20) -> 3016.8553 | DI20: 1 | DJ20: =$DI20*CV20*(1+$DJ$3)*(1+$DJ$4) -> 279.81333 | DK20: =$DI20*CW20*(1+$DJ$3)*(1+$DJ$4) -> 279.81333 | DL20: =$DI20*CX20*(1+$DJ$3)*(1+$DJ$4) -> 279.81333 | DM20: =$DI20*CY20*(1+$DJ$3)*(1+$DJ$4) -> 279.81333 | DN20: =$DI20*CZ20*(1+$DJ$3)*(1+$DJ$4) -> 279.81333 | DO20: =$DI20*DA20*(1+$DJ$3)*(1+$DJ$4) -> 279.81333 | DP20: =$DI20*DB20*(1+$DJ$3)*(1+$DJ$4) -> 279.81333 | DQ20: =$DI20*DC20*(1+$DJ$3)*(1+$DJ$4) -> 279.81333 | ... DU20: =$DI20*DG20*(1+$DJ$3)*(1+$DJ$4) -> 279.81333 | DV20: =SUM(DJ20:DU20) -> 3357.76 | DW20: 1 | DX20: =$DW20*DJ20*(1+$DX$3)*(1+$DX$4) -> 311.43224 | DY20: =$DW20*DK20*(1+$DX$3)*(1+$DX$4) -> 311.43224 | DZ20: =$DW20*DL20*(1+$DX$3)*(1+$DX$4) -> 311.43224 | EA20: =$DW20*DM20*(1+$DX$3)*(1+$DX$4) -> 311.43224 | EB20: =$DW20*DN20*(1+$DX$3)*(1+$DX$4) -> 311.43224 | EC20: =$DW20*DO20*(1+$DX$3)*(1+$DX$4) -> 311.43224 | ED20: =$DW20*DP20*(1+$DX$3)*(1+$DX$4) -> 311.43224 | EE20: =$DW20*DQ20*(1+$DX$3)*(1+$DX$4) -> 311.43224 | ... EI20: =$DW20*DU20*(1+$DX$3)*(1+$DX$4) -> 311.43224 | EJ20: =SUM(DX20:EI20) -> 3737.1868
